Workbook

Sheet Hoja1
D2: PANDERETA | G2: 18 HUECOS | N2: TECHO 12 | Q2: TECHO 15 | S2: ARTESANAL | U2: TECHO 08
B3: FECHA | C3: CLIENTE | D3: SIPAN | E3: CERAMICOS | F3: CALCA | G3: CERAMICOS | H3: TORRE FUERTE | I3: LARK | J3: FORTALEZA | K3: CRUZ CHALPON | L3: TAISON | M3: SIPAN | N3: LARK | O3: ITAL | P3: FORTALEZA | Q3: ITAL | R3: FORTALEZA | S3: BODOQUE | T3: PEQUEÑO | U3: CERAMICOS
A4: INGRESO | C4: INICIAL | D4: 5232 | E4: 904 | F4: 304 | G4: 1136 | H4: 1470 | I4: 885 | J4: 4499 | K4: 1652 | L4: 402 | M4: 103 | N4: 11 | O4: 1022 | P4: 416 | Q4: 1721 | R4: 517 | S4: 1125 | T4: 2358 | U4: 52
B5: 45203 | C5: M5P-711 | O5: 1200
B6: 45203 | C6: AZABACHE | D6: 4312
B7: 45204 | C7: M6I-897 | T7: 3000
B8: 45205 | C8: DEVOLUCION | T8: 500
B9: 45208 | C9: M5P-711 | T9: 300
B10: 45208 | C10: AZABACHE | D10: 2600
B11: 45210 | C11: AZABACHE | D11: 4110
B12: 45211 | C12: AZABACHE | D12: 816
B13: 45211 | C13: AZABACHE | D13: 4140
B14: 45213 | C14: M5P-711 | S14: 3000
B15: 45213 | C15: M6I-897 | O15: 1200
A17: SALIDADA | B17: 45202 | C17: VENTAS H&C | T17: 20
B18: 45202 | C18: VENTAS H&C | T18: 20
B19: 45202 | C19: VENTAS H&C | H19: 150
B20: 45202 | C20: VENTAS H&C | D20: 1000
B21: 45202 | C21: VENTAS H&C | O21: 530
B22: 45203 | C22: VENTAS H&C | S22: 500
B23: 45203 | C23: VENTAS H&C | T23: 1000
B24: 45203 | C24: VENTAS H&C | T24: =20+20 -> 40
B25: 45203 | C25: VENTAS H&C | D25: 500
B26: 45203 | C26: VENTAS H&C | D26: 1000
B27: 45203 | C27: VENTAS H&C | D27: 2500
B28: 45203 | C28: VENTAS H&C | O28: 1000 | P28: 150
B29: 45203 | C29: VENTAS H&C | R29: 140
B30: 45203 | C30: ARCENIO MEJIA | J30: 1000
B31: 45204 | C31: VENTAS H&C | T31: 20
B32: 45204 | C32: VENTAS H&C | T32: 500
B33: 45204 | C33: VENTAS H&C | S33: 250
B34: 45204 | C34: VENTAS H&C | D34: 500
B35: 45204 | C35: VENTAS H&C | D35: 680
B36: 45204 | C36: VENTAS H&C | O36: 180
B37: 45205 | C37: VENTAS H&C | S37: 350
B38: 45205 | C38: VENTAS H&C | J38: 1000
B39: 45205 | C39: VENTAS H&C | J39: 250
B40: 45206 | C40: VENTAS H&C | D40: 1000
B41: 45207 | C41: VENTAS H&C | F41: 20
B42: 45208 | C42: VENTAS H&C | T42: 100
...

Sheet STOCK 16 a 21
D2: PANDERETA | H2: 18 HUECOS | O2: TECHO 12 | R2: TECHO 15 | T2: ARTESANAL | V2: TIPO 4 | W2: TECHO 08
B3: FECHA | C3: CLIENTE | D3: SIPAN | E3: CHALPON | F3: CERAMICOS | G3: CALCA | H3: CERAMICOS | I3: TORRE FUERTE | J3: LARK | K3: FORTALEZA | L3: CRUZ CHALPON | M3: TAISON | N3: SIPAN | O3: LARK | P3: ITAL | Q3: FORTALEZA | R3: ITAL | S3: FORTALEZA | T3: BODOQUE | U3: PEQUEÑO | V3: FORTALEZA | W3: CERAMICOS
A4: INGRESO | C4: INICIAL | D4: 3550 | E4: 2852 | F4: 906 | G4: 206 | H4: 1000 | I4: 1309 | J4: 886 | K4: 2239 | L4: 1652 | M4: 405 | N4: 100 | P4: 701 | R4: 1166 | S4: 308 | T4: 3020 | U4: 3324 | V4: 278 | W4: 52
B5: 45216 | C5: M5P-711 | K5: 3500
B6: 45216 | C6: M6I-897 | O6: 1200
B7: 45218 | C7: M6I-897 | P7: 1200
B8: 45219 | C8: AZABACHE | D8: 2670
B9: 45220 | C9: M5P-711 | R9: 1000
A11: SALIDADA | B11: 45216 | C11: VENTAS H&C | P11: 130 | U11: 20
B12: 45216 | C12: PATRICIA | K12: 1200
B13: 45216 | C13: KELY | O13: 280
B14: 45217 | C14: VENTAS H&C | H14: 450
B15: 45218 | C15: JH | R15: 800
B16: 45218 | C16: VENTAS H&C | P16: =280+780 -> 1060
B17: 45219 | C17: VENTAS H&C | T17: 130 | U17: 70
B18: 45220 | C18: VENTAS H&C | D18: =150+1500+1000 -> 2650 | E18: 6
A24: SALDO | D24: =SUM(D4:D10)-SUM(D11:D23) -> 3570 | E24: =SUM(E4:E10)-SUM(E11:E23) -> 2846 | F24: =SUM(F4:F10)-SUM(F11:F23) -> 906 | G24: =SUM(G4:G10)-SUM(G11:G23) -> 206 | H24: =SUM(H4:H10)-SUM(H11:H23) -> 550 | I24: =SUM(I4:I10)-SUM(I11:I23) -> 1309 | J24: =SUM(J4:J10)-SUM(J11:J23) -> 886 | K24: =SUM(K4:K10)-SUM(K11:K23) -> 4539 | ... W24: =SUM(W4:W10)-SUM(W11:W23) -> 52
D26: =+D24*0.38 -> 1356.6 | E26: =+E24*0.41 -> 1166.86 | F26: =+F24*0.38 -> 344.28 | G26: =+G24*0.48 -> 98.88 | H26: =+H24*0.64 -> 352 | I26: =+I24*0.6 -> 785.4 | J26: =+J24*0.89 -> 788.54 | K26: =+K24*0.68 -> 3086.52 | L26: =+L24*0.66 -> 1090.32 | M26: =+M24*0.7 -> 283.5 | N26: =+N24*0.62 -> 62 | O26: =+O24*2.3 -> 2116 | P26: =+P24*1.77 -> 1258.47 | Q26: =+Q24*2.35 -> 0 | R26: =+R24*1.92 -> 2622.72 | S26: =+S24*2.45 -> 754.6 | T26: =+T24*0.42 -> 1213.8 | U26: =+U24*0.32 -> 1034.88 | V26: =+V24*0.8 -> 222.4 | W26: =+W24*2 -> 104 | X26: =SUM(D26:W26) -> 18741.77
G30: 0.625 | H30: 4
G31: 0.5 | H31: 14
G32: 12 | H32: 2
G33: 0.375 | H33: 6
G34: 8 | H34: 4
G35: 6 | H35: 2
H36: =SUM(H30:H35) -> 32

Sheet STOCK 22 a 28
D2: PANDERETA | H2: 18 HUECOS | O2: TECHO 12 | R2: TECHO 15 | T2: ARTESANAL | V2: TIPO 4 | W2: TECHO 08
B3: FECHA | C3: CLIENTE | D3: SIPAN | E3: CHALPON | F3: CERAMICOS | G3: CALCA | H3: CERAMICOS | I3: TORRE FUERTE | J3: LARK | K3: FORTALEZA | L3: CRUZ CHALPON | M3: TAISON | N3: SIPAN | O3: LARK | P3: ITAL | Q3: FORTALEZA | R3: ITAL | S3: FORTALEZA | T3: BODOQUE | U3: PEQUEÑO | V3: FORTALEZA | W3: CERAMICOS
A4: INGRESO | C4: INICIAL | D4: ='STOCK 16 a 21'!D24 -> 3570 | E4: ='STOCK 16 a 21'!E24 -> 2846 | F4: ='STOCK 16 a 21'!F24 -> 906 | G4: ='STOCK 16 a 21'!G24 -> 206 | H4: ='STOCK 16 a 21'!H24 -> 550 | I4: ='STOCK 16 a 21'!I24 -> 1309 | J4: ='STOCK 16 a 21'!J24 -> 886 | K4: ='STOCK 16 a 21'!K24 -> 4539 | ... W4: ='STOCK 16 a 21'!W24 -> 52
B5: 45223 | C5: AZABACHE | D5: 2150
B6: 45226 | C6: M5P-711 | T6: 3000
A11: SALIDADA | B11: 45222 | C11: VENTAS H&C | D11: 600 | T11: =2000+500 -> 2500
B12: 45223 | C12: VENTAS H&C | D12: =250+1000 -> 1250
B13: 45224 | C13: VENTAS H&C | D13: 200 | G13: 50 | P13: 20 | T13: 390
B14: 45225 | C14: VENTAS H&C | J14: 500 | U14: 75
A25: SALDO | D25: =SUM(D4:D10)-SUM(D11:D24) -> 3670 | E25: =SUM(E4:E10)-SUM(E11:E24) -> 2846 | F25: =SUM(F4:F10)-SUM(F11:F24) -> 906 | G25: =SUM(G4:G10)-SUM(G11:G24) -> 156 | H25: =SUM(H4:H10)-SUM(H11:H24) -> 550 | I25: =SUM(I4:I10)-SUM(I11:I24) -> 1309 | J25: =SUM(J4:J10)-SUM(J11:J24) -> 386 | K25: =SUM(K4:K10)-SUM(K11:K24) -> 4539 | ... W25: =SUM(W4:W10)-SUM(W11:W24) -> 52
D27: =+D25*0.38 -> 1394.6 | E27: =+E25*0.41 -> 1166.86 | F27: =+F25*0.38 -> 344.28 | G27: =+G25*0.48 -> 74.88 | H27: =+H25*0.64 -> 352 | I27: =+I25*0.6 -> 785.4 | J27: =+J25*0.89 -> 343.54 | K27: =+K25*0.68 -> 3086.52 | L27: =+L25*0.66 -> 1090.32 | M27: =+M25*0.7 -> 283.5 | N27: =+N25*0.62 -> 62 | O27: =+O25*2.3 -> 2116 | P27: =+P25*1.77 -> 1223.07 | Q27: =+Q25*2.35 -> 0 | R27: =+R25*1.92 -> 2622.72 | S27: =+S25*2.45 -> 754.6 | T27: =+T25*0.42 -> 1260 | U27: =+U25*0.32 -> 1010.88 | V27: =+V25*0.8 -> 222.4 | W27: =+W25*2 -> 104 | X27: =SUM(D27:W27) -> 18297.57
Q29: 232
G31: 0.625 | H31: 4
G32: 0.5 | H32: 14
G33: 12 | H33: 2
G34: 0.375 | H34: 6
G35: 8 | H35: 4
G36: 6 | H36: 2
H37: =SUM(H31:H36) -> 32

Sheet STOCK 29 a 04
D2: PANDERETA | H2: 18 HUECOS | O2: TECHO 12 | R2: TECHO 15 | T2: ARTESANAL | V2: TIPO 4 | W2: TECHO 08
B3: FECHA | C3: CLIENTE | D3: SIPAN | E3: CHALPON | F3: CERAM | G3: CALCA | H3: CERAM | I3: TORRE FUERTE | J3: LARK | K3: FORTALEZA | L3: CRUZ CHALPON | M3: TAISON | N3: SIPAN | O3: LARK | P3: ITAL | Q3: FORTALEZA | R3: ITAL | S3: FORTALEZA | T3: BODOQUE | U3: PEQUEÑO | V3: FORTALEZA | W3: CERAM
A4: INGRESO | C4: INICIAL | D4: ='STOCK 22 a 28'!D25 -> 3670 | E4: ='STOCK 22 a 28'!E25 -> 2846 | F4: ='STOCK 22 a 28'!F25 -> 906 | G4: ='STOCK 22 a 28'!G25 -> 156 | H4: ='STOCK 22 a 28'!H25 -> 550 | I4: ='STOCK 22 a 28'!I25 -> 1309 | J4: ='STOCK 22 a 28'!J25 -> 386 | K4: ='STOCK 22 a 28'!K25 -> 4539 | ... W4: ='STOCK 22 a 28'!W25 -> 52
B5: 45229 | C5: M6I-897 | J5: 1000
B6: 45230 | C6: M6I-897 | D6: 500
B7: 45230 | C7: M5P-711 | R7: 150
B8: 45231 | C8: M6I-897 | S8: 560
B9: 45233 | C9: M6I-897 | I9: 2200
B10: 45234 | C10: M6I-897 | D10: 1500
A12: SALIDADA | B12: 45229 | C12: VENTAS H&C | I12: 1200 | K12: 2000 | P12: 6 | S12: 300
B13: 45229 | C13: JH | D13: 2000
B14: 45230 | C14: VENTAS H&C | D14: 50 | M14: 200 | T14: =430+20 -> 450
B15: 45232 | C15: VENTAS H&C | D15: 1000
B16: 45233 | C16: VENTAS H&C | I16: 500 | M16: 100 | P16: 150 | R16: 400
B17: 45234 | C17: VENTAS H&C | D17: 70
A21: SALDO | D21: =SUM(D4:D11)-SUM(D12:D20) -> 2550 | E21: =SUM(E4:E11)-SUM(E12:E20) -> 2846 | F21: =SUM(F4:F11)-SUM(F12:F20) -> 906 | G21: =SUM(G4:G11)-SUM(G12:G20) -> 156 | H21: =SUM(H4:H11)-SUM(H12:H20) -> 550 | I21: =SUM(I4:I11)-SUM(I12:I20) -> 1809 | J21: =SUM(J4:J11)-SUM(J12:J20) -> 1386 | K21: =SUM(K4:K11)-SUM(K12:K20) -> 2539 | ... W21: =SUM(W4:W11)-SUM(W12:W20) -> 52
D23: =+D21*0.38 -> 969 | E23: =+E21*0.41 -> 1166.86 | F23: =+F21*0.38 -> 344.28 | G23: =+G21*0.48 -> 74.88 | H23: =+H21*0.64 -> 352 | I23: =+I21*0.6 -> 1085.4 | J23: =+J21*0.89 -> 1233.54 | K23: =+K21*0.68 -> 1726.52 | L23: =+L21*0.66 -> 1090.32 | M23: =+M21*0.7 -> 73.5 | N23: =+N21*0.62 -> 62 | O23: =+O21*2.3 -> 2116 | P23: =+P21*1.77 -> 946.95 | Q23: =+Q21*2.35 -> 0 | R23: =+R21*1.92 -> 2142.72 | S23: =+S21*2.36 -> 1340.48 | T23: =+T21*0.42 -> 1071 | U23: =+U21*0.32 -> 1010.88 | V23: =+V21*0.8 -> 222.4 | W23: =+W21*2 -> 104 | X23: =SUM(D23:W23) -> 17132.73
S24: =2.45-2.36 -> 0.09
Q25: 232 | S25: =8*S24 -> 0.72
G27: 0.625 | H27: 4
G28: 0.5 | H28: 14
G29: 12 | H29: 2
G30: 0.375 | H30: 6
G31: 8 | H31: 4
G32: 6 | H32: 2
H33: =SUM(H27:H32) -> 32

Sheet STOCK 05 a 11
D2: PANDERETA | H2: 18 HUECOS | O2: TECHO 12 | R2: TECHO 15 | T2: ARTESANAL | V2: TIPO 4 | W2: TECHO 08
B3: FECHA | C3: CLIENTE | D3: SIPAN | E3: CHALPON | F3: CERAM | G3: CALCA | H3: CERAM | I3: TORRE FUERTE | J3: LARK | K3: FORTALEZA | L3: CRUZ CHALPON | M3: TAISON | N3: SIPAN | O3: LARK | P3: ITAL | Q3: FORTALEZA | R3: ITAL | S3: FORTALEZA | T3: BODOQUE | U3: PEQUEÑO | V3: FORTALEZA | W3: CERAM
A4: INGRESO | C4: INICIAL | D4: ='STOCK 29 a 04'!D21 -> 2550 | E4: ='STOCK 29 a 04'!E21 -> 2846 | F4: ='STOCK 29 a 04'!F21 -> 906 | G4: ='STOCK 29 a 04'!G21 -> 156 | H4: ='STOCK 29 a 04'!H21 -> 550 | I4: ='STOCK 29 a 04'!I21 -> 1809 | J4: ='STOCK 29 a 04'!J21 -> 1386 | K4: ='STOCK 29 a 04'!K21 -> 2539 | ... W4: ='STOCK 29 a 04'!W21 -> 52
B5: 45239 | C5: M6I-897 | R5: 340
B6: 45239 | C6: M5P-711 | D6: 4500
B7: 45240 | C7: M6I-897 | D7: 4500 | P7: 650
B8: 45240 | C8: M5P-711 | T8: 2000 | U8: 1000
A12: SALIDADA | B12: 45236 | C12: VENTAS H&C | H12: 550 | T12: 300 | U12: 100
B13: 45237 | C13: VENTAS H&C | I13: 1000 | T13: 1000 | U13: 1000
B14: 45238 | C14: VENTAS H&C | T14: 200 | U14: 400
B15: 45239 | C15: VENTAS H&C | U15: 1000
B16: 45240 | C16: VENTAS H&C | T16: =400+45 -> 445
B17: 45241 | C17: VENTAS H&C | T17: 80
A21: SALDO | D21: =SUM(D4:D11)-SUM(D12:D20) -> 11550 | E21: =SUM(E4:E11)-SUM(E12:E20) -> 2846 | F21: =SUM(F4:F11)-SUM(F12:F20) -> 906 | G21: =SUM(G4:G11)-SUM(G12:G20) -> 156 | H21: =SUM(H4:H11)-SUM(H12:H20) -> 0 | I21: =SUM(I4:I11)-SUM(I12:I20) -> 809 | J21: =SUM(J4:J11)-SUM(J12:J20) -> 1386 | K21: =SUM(K4:K11)-SUM(K12:K20) -> 2539 | ... W21: =SUM(W4:W11)-SUM(W12:W20) -> 52
D23: =2550*0.38+9000*0.36 -> 4209 | E23: =+E21*0.41 -> 1166.86 | F23: =+F21*0.38 -> 344.28 | G23: =+G21*0.48 -> 74.88 | H23: =+H21*0.64 -> 0 | I23: =+I21*0.6 -> 485.4 | J23: =+J21*0.89 -> 1233.54 | K23: =+K21*0.68 -> 1726.52 | L23: =+L21*0.66 -> 1090.32 | M23: =+M21*0.7 -> 73.5 | N23: =+N21*0.62 -> 62 | O23: =+O21*2.3 -> 2116 | P23: =+P21*1.77 -> 2097.45 | Q23: =+Q21*2.35 -> 0 | R23: =+R21*1.92 -> 2795.52 | S23: =+S21*2.36 -> 1340.48 | T23: =+T21*0.42 -> 1060.5 | U23: =+U21*0.32 -> 530.88 | V23: =+V21*0.8 -> 222.4 | W23: =+W21*2 -> 104 | X23: =SUM(D23:W23) -> 20733.53
C25: REAL | D25: 11687 | E25: 2874 | F25: 906 | G25: 206 | H25: 115 | I25: 804 | J25: 1381 | K25: 2515 | L25: 1647 | M25: 96 | N25: 100 | O25: 931 | P25: 1184 | R25: 1510 | S25: 567 | T25: 2107 | U25: 1489 | V25: 288 | W25: 54
C26: DIFERENCIA | D26: =D25-D21 -> 137 | E26: =E25-E21 -> 28 | F26: =F25-F21 -> 0 | G26: =G25-G21 -> 50 | H26: =H25-H21 -> 115 | I26: =I25-I21 -> -5 | J26: =J25-J21 -> -5 | K26: =K25-K21 -> -24 | ... W26: =W25-W21 -> 2

Sheet STOCK 12 a 18
D2: PANDERETA | H2: 18 HUECOS | O2: TECHO 12 | R2: TECHO 15 | T2: ARTESANAL | V2: TIPO 4 | W2: TECHO 08
B3: FECHA | C3: CLIENTE | D3: SIPAN | E3: CHALPON | F3: CERAM | G3: CALCA | H3: CERAM | I3: TORRE FUERTE | J3: LARK | K3: FORTALEZA | L3: CRUZ CHALPON | M3: TAISON | N3: SIPAN | O3: LARK | P3: ITAL | Q3: FORTALEZA | R3: ITAL | S3: FORTALEZA | T3: BODOQUE | U3: PEQUEÑO | V3: FORTALEZA | W3: CERAM
A4: INGRESO | C4: INICIAL | D4: ='STOCK 05 a 11'!D21 -> 11550 | E4: ='STOCK 05 a 11'!E21 -> 2846 | F4: ='STOCK 05 a 11'!F21 -> 906 | G4: ='STOCK 05 a 11'!G21 -> 156 | H4: ='STOCK 05 a 11'!H21 -> 0 | I4: ='STOCK 05 a 11'!I21 -> 809 | J4: ='STOCK 05 a 11'!J21 -> 1386 | K4: ='STOCK 05 a 11'!K21 -> 2539 | ... W4: ='STOCK 05 a 11'!W21 -> 52
B5: 45243 | C5: M6I-897 | R5: 200
B6: 45243 | C6: M5P-711 | D6: 3300
B7: 45244 | C7: JH | H7: 4000
B8: 45247 | C8: M5P-711 | U8: 1000
B9: 45248 | C9: M5P-711 | D9: 4500
A13: SALIDADA | B13: 45242 | C13: VENTAS H&C | G13: =20+30 -> 50
B14: 45243 | C14: VENTAS H&C | D14: =1000+1450 -> 2450 | K14: 1000 | P14: 350 | R14: 24
B15: 45244 | C15: VENTAS H&C | O15: 360 | R15: 300 | U15: 500
B16: 45245 | C16: VENTAS H&C | D16: 2000 | G16: 80 | P16: 50 | T16: 50 | U16: 100
B17: 45246 | C17: VENTAS H&C | D17: 23 | U17: 150
B18: 45247 | C18: VENTAS H&C | D18: =1000+50+500 -> 1550 | N18: 100 | P18: 20 | U18: 20
B19: 45248 | C19: VENTAS H&C | D19: =1000+200 -> 1200 | U19: 300
A22: SALDO | D22: =SUM(D4:D12)-SUM(D13:D21) -> 12127 | E22: =SUM(E4:E12)-SUM(E13:E21) -> 2846 | F22: =SUM(F4:F12)-SUM(F13:F21) -> 906 | G22: =SUM(G4:G12)-SUM(G13:G21) -> 26 | H22: =SUM(H4:H12)-SUM(H13:H21) -> 4000 | I22: =SUM(I4:I12)-SUM(I13:I21) -> 809 | J22: =SUM(J4:J12)-SUM(J13:J21) -> 1386 | K22: =SUM(K4:K12)-SUM(K13:K21) -> 1539 | ... W22: =SUM(W4:W12)-SUM(W13:W21) -> 52
D24: =D22*0.36 -> 4365.72 | E24: =+E22*0.41 -> 1166.86 | F24: =+F22*0.38 -> 344.28 | G24: =+G22*0.48 -> 12.48 | H24: =+H22*0.57 -> 2280 | I24: =+I22*0.6 -> 485.4 | J24: =+J22*0.89 -> 1233.54 | K24: =+K22*0.68 -> 1046.52 | L24: =+L22*0.66 -> 1090.32 | M24: =+M22*0.7 -> 73.5 | N24: =+N22*0.62 -> 0 | O24: =+O22*2.3 -> 1288 | P24: =+P22*1.77 -> 1354.05 | Q24: =+Q22*2.35 -> 0 | R24: =+R22*1.92 -> 2557.44 | S24: =+S22*2.36 -> 1340.48 | T24: =+T22*0.42 -> 1039.5 | U24: =+U22*0.32 -> 508.48 | V24: =+V22*0.8 -> 222.4 | W24: =+W22*2 -> 104 | X24: =SUM(D24:W24) -> 20512.97
C26: REAL
H34: 182015Mj

Sheet STOCK 19 a 25
D2: PANDERETA | H2: 18 HUECOS | O2: TECHO 12 | R2: TECHO 15 | T2: ARTESANAL | V2: TIPO 4 | W2: TECHO 08
B3: FECHA | C3: CLIENTE | D3: SIPAN | E3: CHALPON | F3: CERAM | G3: CALCA | H3: CERAM | I3: TORRE FUERTE | J3: LARK | K3: FORTALEZA | L3: CRUZ CHALPON | M3: TAISON | N3: SIPAN | O3: LARK | P3: ITAL | Q3: FORTALEZA | R3: ITAL | S3: FORTALEZA | T3: BODOQUE | U3: PEQUEÑO | V3: FORTALEZA | W3: CERAM
A4: INGRESO | C4: INICIAL | D4: ='STOCK 12 a 18'!D22 -> 12127 | E4: ='STOCK 12 a 18'!E22 -> 2846 | F4: ='STOCK 12 a 18'!F22 -> 906 | G4: ='STOCK 12 a 18'!G22 -> 26 | H4: ='STOCK 12 a 18'!H22 -> 4000 | I4: ='STOCK 12 a 18'!I22 -> 809 | J4: ='STOCK 12 a 18'!J22 -> 1386 | K4: ='STOCK 12 a 18'!K22 -> 1539 | ... W4: ='STOCK 12 a 18'!W22 -> 52
B5: 45251 | C5: M6I-897 | D5: 500
B6: 45251 | C6: DEV MORANTE | D6: 500
B7: 45252 | C7: M6I-897 | P7: 650
B8: 45254 | C8: M6I-897 | D8: 4500
A14: SALIDADA | B14: 45250 | C14: VENTAS H&C | D14: =500+630 -> 1130 | E14: 500 | H14: =10+50 -> 60 | T14: 20 | U14: 1000
B15: 45251 | C15: VENTAS H&C | D15: 500 | J15: 1 | P15: 150 | T15: 60
B16: 45252 | C16: VENTAS H&C | I16: 700 | P16: 275
B17: 45252 | C17: VENTAS JORDY | D17: 1500
B18: 45253 | C18: VENTAS H&C | D18: =500+1000 -> 1500 | K18: 100 | P18: 50
B19: 45254 | C19: VENTAS H&C | D19: 1000 | K19: =500+1000-90 -> 1410 | P19: 400 | U19: 30
B20: 45254 | C20: VENTAS JORDY | D20: 1000
A24: SALDO | D24: =SUM(D4:D13)-SUM(D14:D23) -> 10997 | E24: =SUM(E4:E13)-SUM(E14:E23) -> 2346 | F24: =SUM(F4:F13)-SUM(F14:F23) -> 906 | G24: =SUM(G4:G13)-SUM(G14:G23) -> 26 | H24: =SUM(H4:H13)-SUM(H14:H23) -> 3940 | I24: =SUM(I4:I13)-SUM(I14:I23) -> 109 | J24: =SUM(J4:J13)-SUM(J14:J23) -> 1385 | K24: =SUM(K4:K13)-SUM(K14:K23) -> 29 | ... W24: =SUM(W4:W13)-SUM(W14:W23) -> 52
D26: =D24*0.36 -> 3958.92 | E26: =+E24*0.41 -> 961.86 | F26: =+F24*0.38 -> 344.28 | G26: =+G24*0.48 -> 12.48 | H26: =+H24*0.57 -> 2245.8 | I26: =+I24*0.6 -> 65.4 | J26: =+J24*0.89 -> 1232.65 | K26: =+K24*0.68 -> 19.72 | L26: =+L24*0.66 -> 1090.32 | M26: =+M24*0.7 -> 73.5 | N26: =+N24*0.62 -> 0 | O26: =+O24*2.3 -> 1288 | P26: =+P24*1.77 -> 955.8 | Q26: =+Q24*2.35 -> 0 | R26: =+R24*1.92 -> 2557.44 | S26: =+S24*2.36 -> 1340.48 | T26: =+T24*0.42 -> 1005.9 | U26: =+U24*0.32 -> 178.88 | V26: =+V24*0.8 -> 222.4 | W26: =+W24*2 -> 104 | X26: =SUM(D26:W26) -> 17657.83
C28: REAL
C29: DIFERENCIA | D29: =D28-D24 -> -10997 | E29: =E28-E24 -> -2346 | F29: =F28-F24 -> -906 | G29: =G28-G24 -> -26 | H29: =H28-H24 -> -3940 | I29: =I28-I24 -> -109 | J29: =J28-J24 -> -1385 | K29: =K28-K24 -> -29 | ... W29: =W28-W24 -> -52
H36: 182015Mj

Sheet STOCK 26 a 02
D2: PANDERETA | H2: 18 HUECOS | O2: TECHO 12 | R2: TECHO 15 | T2: ARTESANAL | V2: TIPO 4 | W2: TECHO 08
B3: FECHA | C3: CLIENTE | D3: SIPAN | E3: CHALPON | F3: CERAM | G3: CALCA | H3: CERAM | I3: TORRE FUERTE | J3: LARK | K3: FORTALEZA | L3: CRUZ CHALPON | M3: TAISON | N3: SIPAN | O3: LARK | P3: ITAL | Q3: FORTALEZA | R3: ITAL | S3: FORTALEZA | T3: BODOQUE | U3: PEQUEÑO | V3: FORTALEZA | W3: CERAM
A4: INGRESO | C4: INICIAL | D4: ='STOCK 19 a 25'!D24 -> 10997 | E4: ='STOCK 19 a 25'!E24 -> 2346 | F4: ='STOCK 19 a 25'!F24 -> 906 | G4: ='STOCK 19 a 25'!G24 -> 26 | H4: ='STOCK 19 a 25'!H24 -> 3940 | I4: ='STOCK 19 a 25'!I24 -> 109 | J4: ='STOCK 19 a 25'!J24 -> 1385 | K4: ='STOCK 19 a 25'!K24 -> 29 | ... W4: ='STOCK 19 a 25'!W24 -> 52
B5: 45262 | C5: M6I-897 | T5: 2830
A11: SALIDADA | B11: 45257 | C11: VENTAS JORDY | L11: 1652 | M11: 74
B12: 45257 | C12: MERMAS | K12: 29 | M12: 31
B13: 45257 | C13: VENTAS H&C | D13: 200 | H13: 150 | R13: 250 | T13: =300+20 -> 320 | U13: 250
B14: 45258 | C14: VENTAS H&C | D14: 1 | H14: 23
B15: 45259 | C15: VENTAS H&C | E15: 2000 | T15: 1000
B16: 45260 | C16: VENTAS H&C | D16: =1000+1000 -> 2000 | H16: 490
B17: 45261 | C17: VENTAS H&C | O17: 360 | P17: 30 | R17: 20
B18: 45262 | C18: VENTAS H&C | R18: 600
A21: SALDO | D21: =SUM(D4:D10)-SUM(D11:D20) -> 8796 | E21: =SUM(E4:E10)-SUM(E11:E20) -> 346 | F21: =SUM(F4:F10)-SUM(F11:F20) -> 906 | G21: =SUM(G4:G10)-SUM(G11:G20) -> 26 | H21: =SUM(H4:H10)-SUM(H11:H20) -> 3277 | I21: =SUM(I4:I10)-SUM(I11:I20) -> 109 | J21: =SUM(J4:J10)-SUM(J11:J20) -> 1385 | K21: =SUM(K4:K10)-SUM(K11:K20) -> 0 | ... W21: =SUM(W4:W10)-SUM(W11:W20) -> 52
D23: =D21*0.36 -> 3166.56 | E23: =+E21*0.41 -> 141.86 | F23: =+F21*0.38 -> 344.28 | G23: =+G21*0.48 -> 12.48 | H23: =+H21*0.57 -> 1867.89 | I23: =+I21*0.6 -> 65.4 | J23: =+J21*0.89 -> 1232.65 | K23: =+K21*0.68 -> 0 | L23: =+L21*0.66 -> 0 | M23: =+M21*0.7 -> 0 | N23: =+N21*0.62 -> 0 | O23: =+O21*2.3 -> 460 | P23: =+P21*1.77 -> 902.7 | Q23: =+Q21*2.35 -> 0 | R23: =+R21*1.92 -> 887.04 | S23: =+S21*2.36 -> 1340.48 | T23: =+T21*0.42 -> 1640.1 | U23: =+U21*0.32 -> 98.88 | V23: =+V21*0.8 -> 222.4 | W23: =+W21*2 -> 104 | X23: =SUM(D23:W23) -> 12486.72
C25: REAL
C26: DIFERENCIA | D26: =D25-D21 -> -8796 | E26: =E25-E21 -> -346 | F26: =F25-F21 -> -906 | G26: =G25-G21 -> -26 | H26: =H25-H21 -> -3277 | I26: =I25-I21 -> -109 | J26: =J25-J21 -> -1385 | K26: =K25-K21 -> 0 | ... W26: =W25-W21 -> -52
H33: 182015Mj

Sheet STOCK 03 a 09
D2: PANDERETA | H2: 18 HUECOS | O2: TECHO 12 | R2: TECHO 15 | T2: ARTESANAL | V2: TIPO 4 | W2: TECHO 08
B3: FECHA | C3: CLIENTE | D3: SIPAN | E3: CHALPON | F3: CERAM | G3: CALCA | H3: CERAM | I3: TORRE FUERTE | J3: LARK | K3: FORTALEZA | L3: CRUZ CHALPON | M3: TAISON | N3: SIPAN | O3: LARK | P3: ITAL | Q3: FORTALEZA | R3: ITAL | S3: FORTALEZA | T3: BODOQUE | U3: PEQUEÑO | V3: FORTALEZA | W3: CERAM
A4: INGRESO | D4: ='STOCK 26 a 02'!D21 -> 8796 | E4: ='STOCK 26 a 02'!E21 -> 346 | F4: ='STOCK 26 a 02'!F21 -> 906 | G4: ='STOCK 26 a 02'!G21 -> 26 | H4: ='STOCK 26 a 02'!H21 -> 3277 | I4: ='STOCK 26 a 02'!I21 -> 109 | J4: ='STOCK 26 a 02'!J21 -> 1385 | K4: ='STOCK 26 a 02'!K21 -> 0 | ... W4: ='STOCK 26 a 02'!W21 -> 52
B5: 45265 | C5: M5P-711 | K5: 1500
B6: 45267 | C6: M6I-897 | D6: 4500 | P6: 700 | R6: 500
B7: 45268 | C7: M5P-711 | U7: 3000
B8: 45269 | C8: M6I-897 | K8: 1500
A11: SALIDADA | B11: 45264 | C11: H&C VENTAS | D11: 500 | P11: 230
B12: 45265 | C12: H&C VENTAS | D12: 1000 | K12: 500 | P12: =30+80 -> 110
B13: 45266 | C13: H&C VENTAS | J13: 1000 | P13: 90
B14: 45267 | C14: H&C VENTAS | T14: =5+10 -> 15
B15: 45268 | C15: H&C VENTAS | K15: 500
B16: 45269 | C16: H&C VENTAS | E16: 300
A21: SALDO | D21: =SUM(D4:D10)-SUM(D11:D20) -> 11796 | E21: =SUM(E4:E10)-SUM(E11:E20) -> 46 | F21: =SUM(F4:F10)-SUM(F11:F20) -> 906 | G21: =SUM(G4:G10)-SUM(G11:G20) -> 26 | H21: =SUM(H4:H10)-SUM(H11:H20) -> 3277 | I21: =SUM(I4:I10)-SUM(I11:I20) -> 109 | J21: =SUM(J4:J10)-SUM(J11:J20) -> 385 | K21: =SUM(K4:K10)-SUM(K11:K20) -> 2000 | ... W21: =SUM(W4:W10)-SUM(W11:W20) -> 52
D23: =D21*0.36 -> 4246.56 | E23: =+E21*0.41 -> 18.86 | F23: =+F21*0.38 -> 344.28 | G23: =+G21*0.48 -> 12.48 | H23: =+H21*0.57 -> 1867.89 | I23: =+I21*0.6 -> 65.4 | J23: =+J21*0.89 -> 342.65 | K23: =+K21*0.68 -> 1360 | L23: =+L21*0.66 -> 0 | M23: =+M21*0.7 -> 0 | N23: =+N21*0.62 -> 0 | O23: =+O21*2.3 -> 460 | P23: =+P21*1.77 -> 1380.6 | Q23: =+Q21*2.35 -> 0 | R23: =+R21*1.92 -> 1847.04 | S23: =+S21*2.36 -> 1340.48 | T23: =+T21*0.42 -> 1633.8 | U23: =+U21*0.32 -> 1058.88 | V23: =+V21*0.8 -> 222.4 | W23: =+W21*2 -> 104 | X23: =SUM(D23:W23) -> 16305.32

Sheet STOCK 10 a 16
D2: PANDERETA | H2: 18 HUECOS | O2: TECHO 12 | R2: TECHO 15 | T2: ARTESANAL | V2: TIPO 4 | W2: TECHO 08
B3: FECHA | C3: CLIENTE | D3: SIPAN | E3: CHALPON | F3: CERAM | G3: CALCA | H3: CERAM | I3: TORRE FUERTE | J3: LARK | K3: FORTALEZA | L3: CRUZ CHALPON | M3: TAISON | N3: SIPAN | O3: LARK | P3: ITAL | Q3: FORTALEZA | R3: ITAL | S3: FORTALEZA | T3: BODOQUE | U3: PEQUEÑO | V3: FORTALEZA | W3: CERAM
A4: INGRESO | D4: ='STOCK 03 a 09'!D21 -> 11796 | E4: ='STOCK 03 a 09'!E21 -> 46 | F4: ='STOCK 03 a 09'!F21 -> 906 | G4: ='STOCK 03 a 09'!G21 -> 26 | H4: ='STOCK 03 a 09'!H21 -> 3277 | I4: ='STOCK 03 a 09'!I21 -> 109 | J4: ='STOCK 03 a 09'!J21 -> 385 | K4: ='STOCK 03 a 09'!K21 -> 2000 | ... W4: ='STOCK 03 a 09'!W21 -> 52
B5: 45272 | C5: M6I-897 | J5: 2458
B6: 45272 | C6: M5P-711 | P6: 1200 | Q6: 600 | S6: 500
B7: 45273 | C7: M6I-897 | R7: 1000
B8: 45275 | C8: M6I-897 | D8: 4500
A11: SALIDADA | B11: 45271 | C11: VENTAS H&C | D11: =3000+200 -> 3200 | H11: 28 | P11: 800 | R11: 450 | U11: 1000
B12: 45272 | C12: VENTAS H&C | J12: 370
B13: 45273 | C13: VENTAS H&C | D13: 70
B14: 45274 | C14: VENTAS H&C | D14: 1000 | K14: 1000 | P14: 250 | R14: =50+34 -> 84 | T14: 35 | U14: 500
B15: 45275 | C15: VENTAS H&C | D15: 1000 | P15: =30+20 -> 50
B16: 45276 | C16: VENTAS H&C | H16: 1000
A21: SALDO | D21: =SUM(D4:D10)-SUM(D11:D20) -> 11026 | E21: =SUM(E4:E10)-SUM(E11:E20) -> 46 | F21: =SUM(F4:F10)-SUM(F11:F20) -> 906 | G21: =SUM(G4:G10)-SUM(G11:G20) -> 26 | H21: =SUM(H4:H10)-SUM(H11:H20) -> 2249 | I21: =SUM(I4:I10)-SUM(I11:I20) -> 109 | J21: =SUM(J4:J10)-SUM(J11:J20) -> 2473 | K21: =SUM(K4:K10)-SUM(K11:K20) -> 1000 | ... W21: =SUM(W4:W10)-SUM(W11:W20) -> 52
D23: =D21*0.36 -> 3969.36 | E23: =+E21*0.41 -> 18.86 | F23: =+F21*0.38 -> 344.28 | G23: =+G21*0.48 -> 12.48 | H23: =+H21*0.57 -> 1281.93 | I23: =+I21*0.6 -> 65.4 | J23: =+J21*0.89-(2458*0.02) -> 2151.81 | K23: =+K21*0.68 -> 680 | L23: =+L21*0.66 -> 0 | M23: =+M21*0.7 -> 0 | N23: =+N21*0.62 -> 0 | O23: =+O21*2.3 -> 460 | P23: =+P21*1.77 -> 1557.6 | Q23: =+Q21*2.26 -> 1356 | R23: =+R21*1.92 -> 2741.76 | S23: =+S21*2.36 -> 2520.48 | T23: =+T21*0.42 -> 1619.1 | U23: =+U21*0.32 -> 578.88 | V23: =+V21*0.8 -> 222.4 | W23: =+W21*2 -> 104 | X23: =SUM(D23:W23) -> 19684.34
J25: =2458*0.87 -> 2138.46
J26: =15*0.89 -> 13.35

Sheet STOCK 17 a 23
D2: PANDERETA | H2: 18 HUECOS | O2: TECHO 12 | R2: TECHO 15 | T2: ARTESANAL | V2: TIPO 4 | W2: TECHO 08
B3: FECHA | C3: CLIENTE | D3: SIPAN | E3: CHALPON | F3: CERAM | G3: CALCA | H3: CERAM | I3: TORRE FUERTE | J3: LARK | K3: FORTALEZA | L3: CRUZ CHALPON | M3: TAISON | N3: SIPAN | O3: LARK | P3: ITAL | Q3: FORTALEZA | R3: ITAL | S3: FORTALEZA | T3: BODOQUE | U3: PEQUEÑO | V3: FORTALEZA | W3: CERAM
A4: INGRESO | D4: ='STOCK 10 a 16'!D21 -> 11026 | E4: ='STOCK 10 a 16'!E21 -> 46 | F4: ='STOCK 10 a 16'!F21 -> 906 | G4: ='STOCK 10 a 16'!G21 -> 26 | H4: ='STOCK 10 a 16'!H21 -> 2249 | I4: ='STOCK 10 a 16'!I21 -> 109 | J4: ='STOCK 10 a 16'!J21 -> 2473 | K4: ='STOCK 10 a 16'!K21 -> 1000 | ... W4: ='STOCK 10 a 16'!W21 -> 52
B5: 45279 | C5: M6I-897 | K5: 3500
B6: 45279 | C6: M5P-711 | U6: 2000
B7: 45280 | C7: AZABACHE | D7: 3300
B8: 45282 | C8: M5P-711 | T8: 2500
B9: 45283 | C9: M6I-897 | K9: 1500
A11: SALIDADA | B11: 45278 | C11: VENTAS H&C | O11: 200 | T11: 1000 | U11: =20+500 -> 520
B12: 45279 | C12: VENTAS H&C | D12: 1000 | U12: 25
B13: 45280 | C13: VENTAS H&C | D13: 1500 | R13: 5
B14: 45282 | C14: VENTAS H&C | T14: =1000+10 -> 1010 | U14: 10
B15: 45283 | C15: VENTAS H&C | D15: 50
A21: SALDO | D21: =SUM(D4:D10)-SUM(D11:D20) -> 11776 | E21: =SUM(E4:E10)-SUM(E11:E20) -> 46 | F21: =SUM(F4:F10)-SUM(F11:F20) -> 906 | G21: =SUM(G4:G10)-SUM(G11:G20) -> 26 | H21: =SUM(H4:H10)-SUM(H11:H20) -> 2249 | I21: =SUM(I4:I10)-SUM(I11:I20) -> 109 | J21: =SUM(J4:J10)-SUM(J11:J20) -> 2473 | K21: =SUM(K4:K10)-SUM(K11:K20) -> 6000 | ... W21: =SUM(W4:W10)-SUM(W11:W20) -> 52
D23: =D21*0.36 -> 4239.36 | E23: =+E21*0.41 -> 18.86 | F23: =+F21*0.38 -> 344.28 | G23: =+G21*0.48 -> 12.48 | H23: =+H21*0.57 -> 1281.93 | I23: =+I21*0.6 -> 65.4 | J23: =+J21*0.89-(2458*0.02) -> 2151.81 | K23: =+K21*0.68 -> 4080 | L23: =+L21*0.66 -> 0 | M23: =+M21*0.7 -> 0 | N23: =+N21*0.62 -> 0 | O23: =+O21*2.3 -> 0 | P23: =+P21*1.77 -> 1557.6 | Q23: =+Q21*2.26 -> 1356 | R23: =+R21*1.92 -> 2732.16 | S23: =+S21*2.36 -> 2520.48 | T23: =+T21*0.42 -> 1824.9 | U23: =+U21*0.32 -> 1041.28 | V23: =+V21*0.8 -> 222.4 | W23: =+W21*2 -> 104 | X23: =SUM(D23:W23) -> 23552.94
J25: =2458*0.87 -> 2138.46
J26: =15*0.89 -> 13.35

Sheet STOCK 24 a 30
D2: PANDERETA | H2: 18 HUECOS | O2: TECHO 12 | R2: TECHO 15 | T2: ARTESANAL | V2: TIPO 4 | W2: TECHO 08
B3: FECHA | C3: CLIENTE | D3: SIPAN | E3: CHALPON | F3: CERAM | G3: CALCA | H3: CERAM | I3: TORRE FUERTE | J3: LARK | K3: FORTALEZA | L3: CRUZ CHALPON | M3: TAISON | N3: SIPAN | O3: LARK | P3: ITAL | Q3: FORTALEZA | R3: ITAL | S3: FORTALEZA | T3: BODOQUE | U3: PEQUEÑO | V3: FORTALEZA | W3: CERAM
A4: INGRESO | D4: ='STOCK 17 a 23'!D21 -> 11776 | E4: ='STOCK 17 a 23'!E21 -> 46 | F4: ='STOCK 17 a 23'!F21 -> 906 | G4: ='STOCK 17 a 23'!G21 -> 26 | H4: ='STOCK 17 a 23'!H21 -> 2249 | I4: ='STOCK 17 a 23'!I21 -> 109 | J4: ='STOCK 17 a 23'!J21 -> 2473 | K4: ='STOCK 17 a 23'!K21 -> 6000 | ... W4: ='STOCK 17 a 23'!W21 -> 52
B5: 45286 | C5: M6I-897 | J5: 500
B6: 45287 | C6: M5P-711 | E6: 4500
B7: 45289 | C7: M6I-897 | J7: 2000
B8: 45290 | C8: M6I-897 | O8: 1200
A11: SALIDADA | B11: 45286 | C11: VENTAS H&C | T11: 100
B12: 45286 | C12: JORDY H | J12: 2000
B13: 45287 | C13: JORDY H | D13: 2700 | K13: 1000
B14: 45287 | C14: VENTAS H&C | D14: =500+400+2000 -> 2900 | T14: 200
B15: 45288 | C15: VENTAS H&C | D15: 350 | T15: 300
B16: 45289 | C16: VENTAS H&C | H16: 800 | T16: 100
B17: 45290 | C17: VENTAS H&C | D17: =2000+100+1000 -> 3100 | E17: 346 | O17: 900
X19: =+X23-X21 -> 219.71
A21: SALDO | D21: =SUM(D4:D10)-SUM(D11:D20) -> 2726 | E21: =SUM(E4:E10)-SUM(E11:E20) -> 4200 | F21: =SUM(F4:F10)-SUM(F11:F20) -> 906 | G21: =SUM(G4:G10)-SUM(G11:G20) -> 26 | H21: =SUM(H4:H10)-SUM(H11:H20) -> 1449 | I21: =SUM(I4:I10)-SUM(I11:I20) -> 109 | J21: =SUM(J4:J10)-SUM(J11:J20) -> 2973 | K21: =SUM(K4:K10)-SUM(K11:K20) -> 5000 | ... W21: =SUM(W4:W10)-SUM(W11:W20) -> 52 | X21: =SUM(X22:X29) -> 21407.07
D23: =D21*0.36 -> 981.36 | E23: =+E21*0.4 -> 1680 | F23: =+F21*0.38 -> 344.28 | G23: =+G21*0.48 -> 12.48 | H23: =+H21*0.57 -> 825.93 | I23: =+I21*0.6 -> 65.4 | J23: =+J21*0.87 -> 2586.51 | K23: =+K21*0.68 -> 3400 | L23: =+L21*0.66 -> 0 | M23: =+M21*0.7 -> 0 | N23: =+N21*0.62 -> 0 | O23: =+O21*2.22 -> 666 | P23: =+P21*1.77 -> 1557.6 | Q23: =+Q21*2.26 -> 1356 | R23: =+R21*1.92 -> 2732.16 | S23: =+S21*2.36 -> 2520.48 | T23: =+T21*0.42 -> 1530.9 | U23: =+U21*0.32 -> 1041.28 | V23: =+V21*0.8 -> 222.4 | W23: =+W21*2 -> 104 | X23: =SUM(D23:W23) -> 21626.78
D25: 2889 | E25: 4210 | F25: 906 | H25: 1552 | I25: 103 | J25: 2955 | K25: 5020 | O25: 300 | P25: 870 | Q25: 602 | R25: 1444 | S25: 1068 | T25: 3012 | U25: 3042 | V25: 280 | W25: 43
D27: =+D25-D21 -> 163 | E27: =+E25-E21 -> 10 | F27: =+F25-F21 -> 0 | G27: =+G25-G21 -> -26 | H27: =+H25-H21 -> 103 | I27: =+I25-I21 -> -6 | J27: =+J25-J21 -> -18 | K27: =+K25-K21 -> 20 | ... W27: =+W25-W21 -> -9
D28: =+D27*0.36 -> 58.68 | E28: =+E27*0.4 -> 4 | H28: =+H27*0.57 -> 58.71 | K28: =+K27*0.68 -> 13.6 | Q28: =+Q27*2.26 -> 4.52 | R28: =+R27*1.92 -> 40.32 | V28: =+V27*0.8 -> 1.6 | X28: =SUM(D28:W28) -> 181.43
F29: =F27*0.38 -> 0 | G29: =G27*0.48 -> -12.48 | I29: =I27*0.6 -> -3.6 | J29: =J27*0.87 -> -15.66 | P29: =P27*1.77 -> -17.7 | T29: =T27*0.42 -> -265.86 | U29: =U27*0.32 -> -67.84 | W29: =W27*2 -> -18 | X29: =SUM(D29:W29) -> -401.14

Sheet STOCK 31 a 06
D2: PANDERETA | H2: 18 HUECOS | O2: TECHO 12 | R2: TECHO 15 | U2: ARTESANAL | W2: TIPO 4 | X2: TECHO 08
B3: FECHA | C3: CLIENTE | D3: SIPAN | E3: CHALPON | F3: CERAM | G3: CALCA | H3: CERAM | I3: TORRE FUERTE | J3: LARK | K3: FORTALEZA | L3: CRUZ CHALPON | M3: TAISON | N3: SIPAN | O3: LARK | P3: ITAL | Q3: FORTALEZA | R3: ITAL | T3: FORTALEZA | U3: BODOQUE | V3: PEQUEÑO | W3: FORTALEZA | X3: CERAM
A4: INGRESO | D4: ='STOCK 24 a 30'!D25 -> 2889 | E4: ='STOCK 24 a 30'!E25 -> 4210 | F4: ='STOCK 24 a 30'!F25 -> 906 | G4: ='STOCK 24 a 30'!G25 -> 0 | H4: ='STOCK 24 a 30'!H25 -> 1552 | I4: ='STOCK 24 a 30'!I25 -> 103 | J4: ='STOCK 24 a 30'!J25 -> 2955 | K4: ='STOCK 24 a 30'!K25 -> 5020 | ... R4: ='STOCK 24 a 30'!R25 -> 1444 | T4: ='STOCK 24 a 30'!S25 -> 1068 | U4: ='STOCK 24 a 30'!T25 -> 3012 | V4: ='STOCK 24 a 30'!U25 -> 3042 | W4: ='STOCK 24 a 30'!V25 -> 280 | X4: ='STOCK 24 a 30'!W25 -> 43
B5: 45293 | C5: M6I-897 | S5: 500
B6: 45296 | C6: M6I-897 | D6: 4500
B7: 45297 | C7: M6I-897 | D7: 4500
B8: 45297 | C8: M5P-711 | P8: 700 | R8: 300
A11: SALIDADA | B11: 45293 | C11: VENTAS H&C | D11: 700 | U11: 150
B12: 45294 | C12: VENTAS H&C | K12: 220 | R12: 590 | U12: 50
B13: 45295 | C13: VENTAS H&C | D13: =2000+50 -> 2050
B14: 45296 | C14: VENTAS H&C | D14: 2000 | U14: 100 | V14: 100
B15: 45297 | C15: VENTAS H&C | J15: 200 | V15: 300
A21: SALDO | D21: =SUM(D4:D10)-SUM(D11:D20) -> 7139 | E21: =SUM(E4:E10)-SUM(E11:E20) -> 4210 | F21: =SUM(F4:F10)-SUM(F11:F20) -> 906 | G21: =SUM(G4:G10)-SUM(G11:G20) -> 0 | H21: =SUM(H4:H10)-SUM(H11:H20) -> 1552 | I21: =SUM(I4:I10)-SUM(I11:I20) -> 103 | J21: =SUM(J4:J10)-SUM(J11:J20) -> 2755 | K21: =SUM(K4:K10)-SUM(K11:K20) -> 4800 | ... X21: =SUM(X4:X10)-SUM(X11:X20) -> 43
D23: =D21*0.36 -> 2570.04 | E23: =+E21*0.4 -> 1684 | F23: =+F21*0.38 -> 344.28 | G23: =+G21*0.48 -> 0 | H23: =+H21*0.57 -> 884.64 | I23: =+I21*0.6 -> 61.8 | J23: =+J21*0.87 -> 2396.85 | K23: =+K21*0.68 -> 3264 | L23: =+L21*0.66 -> 0 | M23: =+M21*0.7 -> 0 | N23: =+N21*0.62 -> 0 | O23: =+O21*2.22 -> 666 | P23: =+P21*1.77 -> 2778.9 | Q23: =+Q21*2.26 -> 1360.52 | R23: =+R21*1.92 -> 2215.68 | S23: =+S21*2.47 -> 1235 | T23: =+T21*2.36 -> 2520.48 | U23: =+U21*0.42 -> 1139.04 | V23: =+V21*0.32 -> 845.44 | W23: =+W21*0.8 -> 224 | X23: =+X21*2 -> 86
X25: =SUM(D23:X23) -> 24276.67

Sheet STOCK 07 a 13
D2: PANDERETA | H2: 18 HUECOS | O2: TECHO 12 | R2: TECHO 15 | U2: ARTESANAL | W2: TIPO 4 | X2: TECHO 08
B3: FECHA | C3: CLIENTE | D3: SIPAN | E3: CHALPON | F3: CERAM | G3: CALCA | H3: CERAM | I3: TORRE FUERTE | J3: LARK | K3: FORTALEZA | L3: CRUZ CHALPON | M3: TAISON | N3: SIPAN | O3: LARK | P3: ITAL | Q3: FORTALEZA | R3: ITAL | T3: FORTALEZA | U3: BODOQUE | V3: PEQUEÑO | W3: FORTALEZA | X3: CERAM
A4: INGRESO | D4: ='STOCK 31 a 06'!D21 -> 7139 | E4: ='STOCK 31 a 06'!E21 -> 4210 | F4: ='STOCK 31 a 06'!F21 -> 906 | G4: ='STOCK 31 a 06'!G21 -> 0 | H4: ='STOCK 31 a 06'!H21 -> 1552 | I4: ='STOCK 31 a 06'!I21 -> 103 | J4: ='STOCK 31 a 06'!J21 -> 2755 | K4: ='STOCK 31 a 06'!K21 -> 4800 | ... X4: ='STOCK 31 a 06'!X21 -> 43
B5: 45300 | C5: M6I-897 | P5: 550
B6: 45301 | C6: M6I-897 | K6: 3500
B7: 45302 | C7: M6I-897 | D7: 4500
A11: SALIDADA | B11: 45298 | C11: VENTAS H&C | E11: 190 | H11: 40
B12: 45299 | C12: VENTAS H&C | D12: =2000+500 -> 2500 | P12: 8 | V12: =100+500+30 -> 630
B13: 45301 | C13: VENTAS H&C | H13: 80
B14: 45302 | C14: VENTAS H&C | D14: 1000
B15: 45303 | C15: VENTAS H&C | D15: 2000
B16: 45304 | C16: VENTAS H&C | P16: 300 | V16: =1000+400 -> 1400
A21: SALDO | D21: =SUM(D4:D10)-SUM(D11:D20) -> 6139 | E21: =SUM(E4:E10)-SUM(E11:E20) -> 4020 | F21: =SUM(F4:F10)-SUM(F11:F20) -> 906 | G21: =SUM(G4:G10)-SUM(G11:G20) -> 0 | H21: =SUM(H4:H10)-SUM(H11:H20) -> 1432 | I21: =SUM(I4:I10)-SUM(I11:I20) -> 103 | J21: =SUM(J4:J10)-SUM(J11:J20) -> 2755 | K21: =SUM(K4:K10)-SUM(K11:K20) -> 8300 | ... X21: =SUM(X4:X10)-SUM(X11:X20) -> 43
D23: =D21*0.36 -> 2210.04 | E23: =+E21*0.4 -> 1608 | F23: =+F21*0.38 -> 344.28 | G23: =+G21*0.48 -> 0 | H23: =+H21*0.57 -> 816.24 | I23: =+I21*0.6 -> 61.8 | J23: =+J21*0.87 -> 2396.85 | K23: =+K21*0.68+(3500*0.02) -> 5714 | L23: =+L21*0.66 -> 0 | M23: =+M21*0.7 -> 0 | N23: =+N21*0.62 -> 0 | O23: =+O21*2.22 -> 666 | P23: =+P21*1.77+(550*0.03) -> 3223.74 | Q23: =+Q21*2.26 -> 1360.52 | R23: =+R21*1.92 -> 2215.68 | S23: =+S21*2.47 -> 1235 | T23: =+T21*2.36 -> 2520.48 | U23: =+U21*0.42 -> 1139.04 | V23: =+V21*0.32 -> 195.84 | W23: =+W21*0.8 -> 224 | X23: =+X21*2 -> 86
X25: =SUM(D23:X23) -> 26017.51

Sheet STOCK 14 a 20
D2: PANDERETA | H2: 18 HUECOS | O2: TECHO 12 | R2: TECHO 15 | U2: ARTESANAL | W2: TIPO 4 | X2: TECHO 08
B3: FECHA | C3: CLIENTE | D3: SIPAN | E3: CHALPON | F3: CERAM | G3: CALCA | H3: CERAM | I3: TORRE FUERTE | J3: LARK | K3: FORTALEZA | L3: CRUZ CHALPON | M3: TAISON | N3: SIPAN | O3: LARK | P3: ITAL | Q3: FORTALEZA | R3: ITAL | T3: FORTALEZA | U3: BODOQUE | V3: PEQUEÑO | W3: FORTALEZA | X3: CERAM
A4: INGRESO | D4: ='STOCK 07 a 13'!D21 -> 6139 | E4: ='STOCK 07 a 13'!E21 -> 4020 | F4: ='STOCK 07 a 13'!F21 -> 906 | G4: ='STOCK 07 a 13'!G21 -> 0 | H4: ='STOCK 07 a 13'!H21 -> 1432 | I4: ='STOCK 07 a 13'!I21 -> 103 | J4: ='STOCK 07 a 13'!J21 -> 2755 | K4: ='STOCK 07 a 13'!K21 -> 8300 | ... X4: ='STOCK 07 a 13'!X21 -> 43
B5: 45307 | C5: M6I-897 | D5: 4500 | R5: 300
B6: 45308 | C6: M5P-711 | D6: 2500
B7: 45309 | C7: M5P-711 | V7: 3500
B8: 45310 | C8: M6I-897 | D8: 4500
B9: 45311 | C9: M6I-897 | H9: 3000 | P9: 1200
B10: 45311 | C10: M5P-711 | R10: 1000
A12: SALIDADA | B12: 45305 | C12: VENTAS H&C | V12: 32
B13: 45306 | C13: VENTAS H&C | K13: 1000 | P13: =500 -> 500
B14: 45306 | C14: ARCENIO | D14: 2000
B15: 45307 | C15: VENTAS H&C | D15: 250 | U15: 500
B16: 45308 | C16: VENTAS H&C | D16: =48+250 -> 298 | P16: 536 | R16: =260+650 -> 910
B17: 45309 | C17: VENTAS H&C | F17: 400 | H17: 380 | V17: 20
B18: 45310 | C18: VENTAS H&C | E18: 450 | H18: 500 | V18: 400
B19: 45311 | C19: VENTAS H&C | P19: 700 | V19: 600
A23: SALDO | D23: =SUM(D4:D11)-SUM(D12:D22) -> 15091 | E23: =SUM(E4:E11)-SUM(E12:E22) -> 3570 | F23: =SUM(F4:F11)-SUM(F12:F22) -> 506 | G23: =SUM(G4:G11)-SUM(G12:G22) -> 0 | H23: =SUM(H4:H11)-SUM(H12:H22) -> 3552 | I23: =SUM(I4:I11)-SUM(I12:I22) -> 103 | J23: =SUM(J4:J11)-SUM(J12:J22) -> 2755 | K23: =SUM(K4:K11)-SUM(K12:K22) -> 7300 | ... X23: =SUM(X4:X11)-SUM(X12:X22) -> 43
D25: =D23*0.36-11500*0.01 -> 5317.76 | E25: =+E23*0.4 -> 1428 | F25: =+F23*0.38 -> 192.28 | G25: =+G23*0.48 -> 0 | H25: =+H23*0.57+3000*0.02 -> 2084.64 | I25: =+I23*0.6 -> 61.8 | J25: =+J23*0.87 -> 2396.85 | K25: =+K23*0.68+(3500*0.02) -> 5034 | L25: =+L23*0.66 -> 0 | M25: =+M23*0.7 -> 0 | N25: =+N23*0.62 -> 0 | O25: =+O23*2.22 -> 666 | P25: =+P23*1.8 -> 2296.8 | Q25: =+Q23*2.26 -> 1360.52 | R25: =+R23*1.92+1300*0.03 -> 3003.48 | S25: =+S23*2.47 -> 1235 | T25: =+T23*2.36 -> 2520.48 | U25: =+U23*0.42 -> 929.04 | V25: =+V23*0.32 -> 979.2 | W25: =+W23*0.8 -> 224 | X25: =+X23*2 -> 86
X27: =SUM(D25:X25) -> 29815.85

Sheet STOCK 21 a 27
D2: PANDERETA | H2: 18 HUECOS | O2: TECHO 12 | R2: TECHO 15 | U2: ARTESANAL | W2: TIPO 4 | X2: TECHO 08
B3: FECHA | C3: CLIENTE | D3: SIPAN | E3: CHALPON | F3: CERAM | G3: CALCA | H3: CERAM | I3: TORRE FUERTE | J3: LARK | K3: FORTALEZA | L3: CRUZ CHALPON | M3: TAISON | N3: SIPAN | O3: LARK | P3: ITAL | Q3: FORTALEZA | R3: ITAL | S3: LARK | T3: FORTALEZA | U3: BODOQUE | V3: PEQUEÑO | W3: FORTALEZA | X3: CERAM
A4: INGRESO | D4: ='STOCK 14 a 20'!D23 -> 15091 | E4: ='STOCK 14 a 20'!E23 -> 3570 | F4: ='STOCK 14 a 20'!F23 -> 506 | G4: ='STOCK 14 a 20'!G23 -> 0 | H4: ='STOCK 14 a 20'!H23 -> 3552 | I4: ='STOCK 14 a 20'!I23 -> 103 | J4: ='STOCK 14 a 20'!J23 -> 2755 | K4: ='STOCK 14 a 20'!K23 -> 7300 | ... X4: ='STOCK 14 a 20'!X23 -> 43
B5: 45314 | C5: M6I-897 | D5: 4500
B6: 45315 | C6: M6I-897 | P6: 750
B7: 45316 | C7: M5P-711 | H7: 650
B8: 45317 | C8: M6I-897 | U8: 2150
B9: 45317 | C9: M5P-711 | D9: 500
A12: SALIDADA | B12: 45313 | C12: VENTAS H&C | D12: 70 | K12: 3000 | R12: 600
B13: 45313 | C13: VENTA JORDY | D13: 3000
B14: 45314 | C14: VENTAS H&C | U14: 200 | V14: 100
B15: 45315 | C15: VENTAS H&C | D15: =1000+1000 -> 2000 | V15: 250
B16: 45316 | C16: VENTA JORDY | D16: 1500 | K16: 500
B17: 45317 | C17: VENTA JORDY | D17: 2000 | U17: 1000
B18: 45317 | C18: VENTAS H&C | V18: 30
B19: 45318 | C19: VENTAS H&C | D19: 1000 | J19: 470 | V19: 6
A24: SALDO | D24: =SUM(D4:D11)-SUM(D12:D23) -> 10521 | E24: =SUM(E4:E11)-SUM(E12:E23) -> 3570 | F24: =SUM(F4:F11)-SUM(F12:F23) -> 506 | G24: =SUM(G4:G11)-SUM(G12:G23) -> 0 | H24: =SUM(H4:H11)-SUM(H12:H23) -> 4202 | I24: =SUM(I4:I11)-SUM(I12:I23) -> 103 | J24: =SUM(J4:J11)-SUM(J12:J23) -> 2285 | K24: =SUM(K4:K11)-SUM(K12:K23) -> 3800 | ... X24: =SUM(X4:X11)-SUM(X12:X23) -> 43
D26: =D24*0.35 -> 3682.35 | E26: =+E24*0.4 -> 1428 | F26: =+F24*0.38 -> 192.28 | G26: =+G24*0.48 -> 0 | H26: =+H24*0.59-552*0.02 -> 2468.14 | I26: =+I24*0.6 -> 61.8 | J26: =+J24*0.87 -> 1987.95 | K26: =+K24*0.68+(3500*0.02) -> 2654 | L26: =+L24*0.66 -> 0 | M26: =+M24*0.7 -> 0 | N26: =+N24*0.62 -> 0 | O26: =+O24*2.22 -> 666 | P26: =+P24*1.8 -> 3646.8 | Q26: =+Q24*2.26 -> 1360.52 | R26: =+R24*1.95 -> 1840.8 | S26: =+S24*2.47 -> 1235 | T26: =+T24*2.36 -> 2520.48 | U26: =+U24*0.42 -> 1328.04 | V26: =+V24*0.32 -> 855.68 | W26: =+W24*0.8 -> 224 | X26: =+X24*2 -> 86
H28: 2384.64 | X28: =SUM(D26:X26) -> 26237.84

Sheet STOCK 28 a 03
D2: PANDERETA | H2: 18 HUECOS | O2: TECHO 12 | R2: TECHO 15 | U2: ARTESANAL | W2: TIPO 4 | X2: TECHO 08
B3: FECHA | C3: CLIENTE | D3: SIPAN | E3: CHALPON | F3: CERAM | G3: CALCA | H3: CERAM | I3: TORRE FUERTE | J3: LARK | K3: FORTALEZA | L3: CRUZ CHALPON | M3: TAISON | N3: SIPAN | O3: LARK | P3: ITAL | Q3: FORTALEZA | R3: ITAL | S3: LARK | T3: FORTALEZA | U3: BODOQUE | V3: PEQUEÑO | W3: FORTALEZA | X3: CERAM
A4: INGRESO | D4: ='STOCK 21 a 27'!D24 -> 10521 | E4: ='STOCK 21 a 27'!E24 -> 3570 | F4: ='STOCK 21 a 27'!F24 -> 506 | G4: ='STOCK 21 a 27'!G24 -> 0 | H4: ='STOCK 21 a 27'!H24 -> 4202 | I4: ='STOCK 21 a 27'!I24 -> 103 | J4: ='STOCK 21 a 27'!J24 -> 2285 | K4: ='STOCK 21 a 27'!K24 -> 3800 | ... X4: ='STOCK 21 a 27'!X24 -> 43
B5: 45322 | C5: M6I-897 | D5: 4000
B6: 45322 | C6: M5P-711 | K6: 3500
B7: 45323 | C7: M6I-897 | R7: 1000
B8: 45325 | C8: M6I-897 | D8: 4500
B9: 45325 | C9: M5P-711 | U9: 1000 | V9: 500
A11: SALIDADA | B11: 45320 | C11: VENTAS H&C | H11: 100 | R11: 160 | V11: 30
B12: 45320 | C12: VENTA JORDY | K12: 3500
B13: 45321 | C13: VENTA JORDY | D13: 4000
B14: 45321 | C14: VENTAS H&C | D14: =1000+1000 -> 2000
B15: 45322 | C15: VENTA JORDY | R15: 260
B16: 45322 | C16: VENTAS H&C | D16: 150 | P16: 60 | U16: 50
B17: 45323 | C17: VENTA JORDY | D17: 1000
B18: 45323 | C18: VENTAS H&C | R18: 200 | V18: =500+40 -> 540
B19: 45324 | C19: VENTAS H&C | D19: 1000 | U19: 170 | V19: 300
B20: 45324 | C20: VENTA JORDY | E20: 1000
B21: 45325 | C21: VENTAS H&C | V21: 12
A24: SALDO | D24: =SUM(D4:D10)-SUM(D11:D23) -> 10871 | E24: =SUM(E4:E10)-SUM(E11:E23) -> 2570 | F24: =SUM(F4:F10)-SUM(F11:F23) -> 506 | G24: =SUM(G4:G10)-SUM(G11:G23) -> 0 | H24: =SUM(H4:H10)-SUM(H11:H23) -> 4102 | I24: =SUM(I4:I10)-SUM(I11:I23) -> 103 | J24: =SUM(J4:J10)-SUM(J11:J23) -> 2285 | K24: =SUM(K4:K10)-SUM(K11:K23) -> 3800 | ... X24: =SUM(X4:X10)-SUM(X11:X23) -> 43
D26: =D24*0.35 -> 3804.85 | E26: =+E24*0.4 -> 1028 | F26: =+F24*0.38 -> 192.28 | G26: =+G24*0.48 -> 0 | H26: =+H24*0.59-452*0.02 -> 2411.14 | I26: =+I24*0.6 -> 61.8 | J26: =+J24*0.87 -> 1987.95 | K26: =+K24*0.7 -> 2660 | L26: =+L24*0.66 -> 0 | M26: =+M24*0.7 -> 0 | N26: =+N24*0.62 -> 0 | O26: =+O24*2.22 -> 666 | P26: =+P24*1.8 -> 3538.8 | Q26: =+Q24*2.26 -> 1360.52 | R26: =+R24*1.95 -> 2581.8 | S26: =+S24*2.47 -> 1235 | T26: =+T24*2.36 -> 2520.48 | U26: =+U24*0.42 -> 1655.64 | V26: =+V24*0.32 -> 733.44 | W26: =+W24*0.8 -> 224 | X26: =+X24*2 -> 86
H28: 2384.64 | X28: =SUM(D26:X26) -> 26747.7

Sheet STOCK 04 a 10
D2: PANDERETA | H2: 18 HUECOS | O2: TECHO 12 | R2: TECHO 15 | U2: ARTESANAL | W2: SUPER KK | X2: TIPO 4 | Y2: TECHO 08
B3: FECHA | C3: CLIENTE | D3: SIPAN | E3: CHALPON | F3: CERAM | G3: FORTALEZA | H3: CERAM | I3: TORRE FUERTE | J3: LARK | K3: FORTALEZA | L3: CRUZ CHALPON | M3: TAISON | N3: SIPAN | O3: LARK | P3: ITAL | Q3: FORTALEZA | R3: ITAL | S3: LARK | T3: FORTALEZA | U3: BODOQUE | V3: PEQUEÑO | W3: CERAMICOS | X3: FORTALEZA | Y3: CERAM
A4: INGRESO | D4: ='STOCK 28 a 03'!D24 -> 10871 | E4: ='STOCK 28 a 03'!E24 -> 2570 | F4: ='STOCK 28 a 03'!F24 -> 506 | G4: ='STOCK 28 a 03'!G24 -> 0 | H4: ='STOCK 28 a 03'!H24 -> 4102 | I4: ='STOCK 28 a 03'!I24 -> 103 | J4: ='STOCK 28 a 03'!J24 -> 2285 | K4: ='STOCK 28 a 03'!K24 -> 3800 | ... V4: ='STOCK 28 a 03'!V24 -> 2292 | X4: ='STOCK 28 a 03'!W24 -> 280 | Y4: ='STOCK 28 a 03'!X24 -> 43
B5: 45327 | C5: M8B-893 | N5: 1000
B6: 45329 | C6: M8B-893 | D6: 60
B7: 45329 | C7: M6I-897 | K7: 2000
B8: 45329 | C8: M5P-711 | V8: 3000
B9: 45330 | C9: M8B-893 | G9: 5060
B10: 45330 | C10: M6I-897 | U10: 2000 | W10: 500
B11: 45331 | C11: M8B-893 | D11: 1060
B12: 45331 | C12: M6I-897
B13: 45331 | C13: M5P-711 | V13: 3000
A16: SALIDADA | B16: 45326 | C16: VENTAS H&C | U16: 50
B17: 45327 | C17: VENTAS H&C | U17: =500+500 -> 1000
B18: 45328 | C18: VENTAS H&C | D18: 1000 | E18: 400 | U18: 1000 | V18: =200 -> 200
B19: 45329 | C19: VENTAS H&C | H19: 100 | K19: 1000 | V19: 1500
B20: 45330 | C20: VENTAS H&C | E20: 500 | H20: 6 | U20: 1000 | V20: =300+25 -> 325
B21: 45330 | C21: VENTA JORDY | J21: 2000 | U21: 1000
B22: 45331 | C22: VENTAS H&C | H22: 200 | R22: =10+400 -> 410 | V22: =152+200 -> 352
B23: 45331 | C23: VENTA JORDY | R23: 362
B24: 45332 | C24: VENTAS H&C | D24: =500+1000 -> 1500 | P24: 400 | U24: 200
A27: SALDO | D27: =SUM(D4:D15)-SUM(D16:D26) -> 9491 | E27: =SUM(E4:E15)-SUM(E16:E26) -> 1670 | F27: =SUM(F4:F15)-SUM(F16:F26) -> 506 | G27: =SUM(G4:G15)-SUM(G16:G26) -> 5060 | H27: =SUM(H4:H15)-SUM(H16:H26) -> 3796 | I27: =SUM(I4:I15)-SUM(I16:I26) -> 103 | J27: =SUM(J4:J15)-SUM(J16:J26) -> 285 | K27: =SUM(K4:K15)-SUM(K16:K26) -> 4800 | ... Y27: =SUM(Y4:Y15)-SUM(Y16:Y26) -> 43
D29: =D27*0.35 -> 3321.85 | E29: =+E27*0.4 -> 668 | F29: =+F27*0.38 -> 192.28 | G29: =+G27*0.45 -> 2277 | H29: =+H27*0.59-146*0.02 -> 2236.72 | I29: =+I27*0.6 -> 61.8 | J29: =+J27*0.87 -> 247.95 | K29: =+K27*0.7 -> 3360 | L29: =+L27*0.66 -> 0 | M29: =+M27*0.7 -> 0 | N29: =+N27*0.55 -> 550 | O29: =+O27*2.22 -> 666 | P29: =+P27*1.8 -> 2818.8 | Q29: =+Q27*2.26 -> 1360.52 | R29: =+R27*1.95 -> 1076.4 | S29: =+S27*2.47 -> 1235 | T29: =+T27*2.36 -> 2520.48 | U29: =+U27*0.42 -> 710.64 | V29: =+V27*0.32 -> 1892.8 | W29: =+W27*2.3 -> 1150 | X29: =+X27*0.8 -> 224 | Y29: =+Y27*2 -> 86
C31: STOCK REAL | D31: 8229 | E31: 1668 | F31: 500 | G31: 5060 | H31: 3883 | J31: 282 | K31: 4790 | N31: 1010 | O31: 300 | P31: 1570 | Q31: 600 | R31: 555 | S31: 500 | T31: 1068 | U31: 2896 | V31: 5998 | W31: 502 | X31: 320 | Y31: =SUM(D29:Y29) -> 26656.24
C33: DIFERENCIA | D33: =+D31-D27 -> -1262 | E33: =+E31-E27 -> -2 | F33: =+F31-F27 -> -6 | G33: =+G31-G27 -> 0 | H33: =+H31-H27 -> 87 | I33: =+I31-I27 -> -103 | J33: =+J31-J27 -> -3 | K33: =+K31-K27 -> -10 | ... X33: =+X31-X27 -> 40
C35: DIF/SOLES | D35: =D33*0.35 -> -441.7 | E35: =E33*0.4 -> -0.8 | F35: =F33*0.38 -> -2.28 | G35: =G33*0.45 -> 0 | H35: =H33*0.59 -> 51.33 | I35: =I33*0.6 -> -61.8 | J35: =J33*0.87 -> -2.61 | K35: =K33*0.7 -> -7 | L35: =L33*0.4 -> 0 | M35: =M33*0.4 -> 0 | N35: =N33*0.55 -> 5.5 | O35: =O33*0.4 -> 0 | P35: =P33*1.8 -> 7.2 | Q35: =Q33*2.26 -> -4.52 | R35: =R33*1.95 -> 5.85 | S35: =S33*0.4 -> 0 | T35: =T33*0.4 -> 0 | U35: =U33*0.42 -> 505.68 | V35: =V33*0.32 -> 26.56 | W35: =W33*2.3 -> 4.6 | X35: =X33*0.8 -> 32

Sheet STOCK 11 a 17
D2: PANDERETA | H2: 18 HUECOS | O2: TECHO 12 | R2: TECHO 15 | U2: ARTESANAL | W2: SUPER KK | X2: TIPO 4 | Y2: TECHO 08
B3: FECHA | C3: CLIENTE | D3: SIPAN | E3: CHALPON | F3: CERAM | G3: FORTALEZA | H3: CERAM | I3: TORRE FUERTE | J3: LARK | K3: FORTALEZA | L3: CRUZ CHALPON | M3: TAISON | N3: SIPAN | O3: LARK | P3: ITAL | Q3: FORTALEZA | R3: ITAL | S3: LARK | T3: FORTALEZA | U3: BODOQUE | V3: PEQUEÑO | W3: CERAMICOS | X3: FORTALEZA | Y3: CERAM
A4: INGRESO | D4: ='STOCK 04 a 10'!D27 -> 9491 | E4: ='STOCK 04 a 10'!E27 -> 1670 | F4: ='STOCK 04 a 10'!F27 -> 506 | G4: ='STOCK 04 a 10'!G27 -> 5060 | H4: ='STOCK 04 a 10'!H27 -> 3796 | I4: ='STOCK 04 a 10'!I27 -> 103 | J4: ='STOCK 04 a 10'!J27 -> 285 | K4: ='STOCK 04 a 10'!K27 -> 4800 | ... Y4: ='STOCK 04 a 10'!Y27 -> 43
B5: 45334 | C5: M8B-893 | J5: 1500
B6: 45335 | C6: M5P-711 | D6: 4000
B7: 45336 | C7: M6I-897 | R7: 1000
B8: 45337 | C8: M6I-897 | D8: 4500
B9: 45338 | C9: M6I-897 | D9: 4500
B10: 45338 | C10: M5P-711 | U10: 2000
A12: SALIDADA | B12: 45334 | C12: VENTAS H&C | Q12: 530 | R12: 200 | U12: =300+500 -> 800
B13: 45329 | C13: VENTA JORDY | D13: 3000
B14: 45334 | C14: VENTA JORDY | O14: 180
B15: 45335 | C15: VENTA JORDY | K15: 1000
B16: 45335 | C16: VENTAS H&C | H16: 500 | U16: 1000
B17: 45336 | C17: VENTA JORDY | D17: 1000
B18: 45336 | C18: VENTAS H&C | K18: =100+200 -> 300 | U18: 30
B19: 45337 | C19: VENTAS H&C | D19: 500 | K19: 2500
B20: 45338 | C20: VENTAS H&C | K20: =70+8 -> 78
B21: 45339 | C21: VENTAS H&C | U21: 500 | V21: =150+150 -> 300
A27: SALDO | D27: =SUM(D4:D11)-SUM(D12:D26) -> 17991 | E27: =SUM(E4:E11)-SUM(E12:E26) -> 1670 | F27: =SUM(F4:F11)-SUM(F12:F26) -> 506 | G27: =SUM(G4:G11)-SUM(G12:G26) -> 5060 | H27: =SUM(H4:H11)-SUM(H12:H26) -> 3296 | I27: =SUM(I4:I11)-SUM(I12:I26) -> 103 | J27: =SUM(J4:J11)-SUM(J12:J26) -> 1785 | K27: =SUM(K4:K11)-SUM(K12:K26) -> 922 | ... Y27: =SUM(Y4:Y11)-SUM(Y12:Y26) -> 43
D29: =D27*0.35 -> 6296.85 | E29: =+E27*0.4 -> 668 | F29: =+F27*0.38 -> 192.28 | G29: =+G27*0.45 -> 2277 | H29: =+H27*0.59 -> 1944.64 | I29: =+I27*0.6 -> 61.8 | J29: =+J27*0.87 -> 1552.95 | K29: =+K27*0.7 -> 645.4 | L29: =+L27*0.66 -> 0 | M29: =+M27*0.7 -> 0 | N29: =+N27*0.55 -> 550 | O29: =+O27*2.22 -> 266.4 | P29: =+P27*1.8 -> 2818.8 | Q29: =+Q27*2.26 -> 162.72 | R29: =+R27*1.85+(352*0.1) -> 2536.4 | S29: =+S27*2.47 -> 1235 | T29: =+T27*2.36 -> 2520.48 | U29: =+U27*0.42 -> 572.04 | V29: =+V27*0.32 -> 1796.8 | W29: =+W27*2.3 -> 1150 | X29: =+X27*0.8 -> 224 | Y29: =+Y27*2 -> 86
Y31: =SUM(D29:Y29) -> 27557.56
D34: 231

Sheet STOCK 18 a 24
D2: PANDERETA | H2: 18 HUECOS | O2: TECHO 12 | R2: TECHO 15 | U2: ARTESANAL | W2: SUPER KK | X2: TIPO 4 | Y2: TECHO 08
B3: FECHA | C3: CLIENTE | D3: SIPAN | E3: CHALPON | F3: CERAM | G3: FORTALEZA | H3: CERAM | I3: TORRE FUERTE | J3: LARK | K3: FORTALEZA | L3: CRUZ CHALPON | M3: TAISON | N3: SIPAN | O3: LARK | P3: ITAL | Q3: FORTALEZA | R3: ITAL | S3: LARK | T3: FORTALEZA | U3: BODOQUE | V3: PEQUEÑO | W3: CERAMICOS | X3: FORTALEZA | Y3: CERAM
A4: INGRESO | D4: ='STOCK 11 a 17'!D27 -> 17991 | E4: ='STOCK 11 a 17'!E27 -> 1670 | F4: ='STOCK 11 a 17'!F27 -> 506 | G4: ='STOCK 11 a 17'!G27 -> 5060 | H4: ='STOCK 11 a 17'!H27 -> 3296 | I4: ='STOCK 11 a 17'!I27 -> 103 | J4: ='STOCK 11 a 17'!J27 -> 1785 | K4: ='STOCK 11 a 17'!K27 -> 922 | ... Y4: ='STOCK 11 a 17'!Y27 -> 43
B5: 45341 | C5: M8B-897 | R5: 727
B6: 45343 | C6: M6I-897 | K6: 3500
B7: 45344 | C7: M8B-897 | K7: 2000
B8: 45346 | C8: M8B-897 | P8: 500
A11: SALIDADA | B11: 45340 | C11: VENTAS H&C | V11: 150
B12: 45341 | C12: VENTAS H&C | D12: 500
B13: 45342 | C13: VENTAS H&C | R13: 150 | U13: =250+100 -> 350 | W13: 100
B14: 45343 | C14: VENTAS H&C | N14: 100
B15: 45344 | C15: VENTAS H&C | D15: 500 | G15: 1000 | V15: 300
B16: 45345 | C16: VENTAS H&C | H16: 200 | U16: 1012
B17: 45345 | C17: VENTASJORDY | J17: 1700
B18: 45346 | C18: VENTAS H&C | R18: 200
A24: SALDO | D24: =SUM(D4:D10)-SUM(D11:D23) -> 16991 | E24: =SUM(E4:E10)-SUM(E11:E23) -> 1670 | F24: =SUM(F4:F10)-SUM(F11:F23) -> 506 | G24: =SUM(G4:G10)-SUM(G11:G23) -> 4060 | H24: =SUM(H4:H10)-SUM(H11:H23) -> 3096 | I24: =SUM(I4:I10)-SUM(I11:I23) -> 103 | J24: =SUM(J4:J10)-SUM(J11:J23) -> 85 | K24: =SUM(K4:K10)-SUM(K11:K23) -> 6422 | ... Y24: =SUM(Y4:Y10)-SUM(Y11:Y23) -> 43
D26: =D24*0.35 -> 5946.85 | E26: =+E24*0.4 -> 668 | F26: =+F24*0.38 -> 192.28 | G26: =+G24*0.45 -> 1827 | H26: =+H24*0.59 -> 1826.64 | I26: =+I24*0.6 -> 61.8 | J26: =+J24*0.87 -> 73.95 | K26: =+K24*0.7 -> 4495.4 | L26: =+L24*0.66 -> 0 | M26: =+M24*0.7 -> 0 | N26: =+N24*0.55 -> 495 | O26: =+O24*2.22 -> 266.4 | P26: =+P24*1.75+(1566*0.05) -> 3693.8 | Q26: =+Q24*2.26 -> 162.72 | R26: =+R24*1.85+(2*0.1) -> 3198.85 | S26: =+S24*2.47 -> 1235 | T26: =+T24*2.36 -> 2520.48 | U26: =+U24*0.42 -> 0 | V26: =+V24*0.32 -> 1652.8 | W26: =+W24*2.3 -> 920 | X26: =+X24*0.8 -> 224 | Y26: =+Y24*2 -> 86
Y28: =SUM(D26:Y26) -> 29546.97
D31: 231

Sheet STOCK 25 a 02
D2: PANDERETA | H2: 18 HUECOS | O2: TECHO 12 | R2: TECHO 15 | U2: ARTESANAL | W2: SUPER KK | X2: TIPO 4 | Y2: TECHO 08
B3: FECHA | C3: CLIENTE | D3: SIPAN | E3: CHALPON | F3: CERAM | G3: FORTALEZA | H3: CERAM | I3: TORRE FUERTE | J3: LARK | K3: FORTALEZA | L3: CRUZ CHALPON | M3: TAISON | N3: SIPAN | O3: LARK | P3: ITAL | Q3: FORTALEZA | R3: ITAL | S3: LARK | T3: FORTALEZA | U3: BODOQUE | V3: PEQUEÑO | W3: CERAMICOS | X3: FORTALEZA | Y3: CERAM
A4: INGRESO | D4: ='STOCK 18 a 24'!D24 -> 16991 | E4: ='STOCK 18 a 24'!E24 -> 1670 | F4: ='STOCK 18 a 24'!F24 -> 506 | G4: ='STOCK 18 a 24'!G24 -> 4060 | H4: ='STOCK 18 a 24'!H24 -> 3096 | I4: ='STOCK 18 a 24'!I24 -> 103 | J4: ='STOCK 18 a 24'!J24 -> 85 | K4: ='STOCK 18 a 24'!K24 -> 6422 | ... Y4: ='STOCK 18 a 24'!Y24 -> 43
B5: 45349 | C5: M8B-893 | J5: 1000
B6: 45349 | C6: M6I-897 | U6: 3000
B7: 45350 | C7: M6I-897 | P7: 700
B8: 45351 | C8: M8B-893 | W8: 1000
B9: 45351 | C9: M6I-897 | M9: 1000
A11: SALIDADA | B11: 45347 | C11: VENTAS H&C | V11: 100
B12: 45348 | C12: VENTAS H&C | P12: 500 | R12: 500 | T12: 197
B13: 45349 | C13: VENTAS H&C | D13: 1000 | H13: 2000 | J13: 60 | V13: 200
B14: 45350 | C14: VENTAS H&C | H14: 250 | J14: 300 | U14: 1000
B15: 45351 | C15: VENTAS H&C | D15: 200 | P15: 130 | U15: 40
B16: 45352 | C16: VENTAS H&C | D16: =80+100+200 -> 380 | H16: 80 | K16: 1000 | V16: 1300
B17: 45353 | C17: VENTA JORDY | K17: 500 | U17: 1000
B18: 45353 | C18: VENTAS H&C | D18: 200 | U18: =100+150+100+500 -> 850
A24: SALDO | D24: =SUM(D4:D10)-SUM(D11:D23) -> 15211 | E24: =SUM(E4:E10)-SUM(E11:E23) -> 1670 | F24: =SUM(F4:F10)-SUM(F11:F23) -> 506 | G24: =SUM(G4:G10)-SUM(G11:G23) -> 4060 | H24: =SUM(H4:H10)-SUM(H11:H23) -> 766 | I24: =SUM(I4:I10)-SUM(I11:I23) -> 103 | J24: =SUM(J4:J10)-SUM(J11:J23) -> 725 | K24: =SUM(K4:K10)-SUM(K11:K23) -> 4922 | ... Y24: =SUM(Y4:Y10)-SUM(Y11:Y23) -> 43
D26: =D24*0.35 -> 5323.85 | E26: =+E24*0.4 -> 668 | F26: =+F24*0.38 -> 192.28 | G26: =+G24*0.45 -> 1827 | H26: =+H24*0.59 -> 451.94 | I26: =+I24*0.6 -> 61.8 | J26: =+J24*0.87 -> 630.75 | K26: =+K24*0.7 -> 3445.4 | L26: =+L24*0.66 -> 0 | M26: =+M24*0.64 -> 640 | N26: =+N24*0.55 -> 495 | O26: =+O24*2.22 -> 266.4 | P26: =+P24*1.75+(936*0.05) -> 3784.8 | Q26: =+Q24*2.26 -> 162.72 | R26: =+R24*1.85 -> 2273.65 | S26: =+S24*2.47 -> 1235 | T26: =+T24*2.36 -> 2055.56 | U26: =+U24*0.42 -> 46.2 | V26: =+V24*0.32 -> 1140.8 | W26: =+W24*2+(400*0.3) -> 2920 | X26: =+X24*0.8 -> 224 | Y26: =+Y24*2 -> 86
Y28: =SUM(D26:Y26) -> 27931.15
D31: 231

Sheet STOCK 03 a 009
D2: PANDERETA | H2: 18 HUECOS | O2: TECHO 12 | R2: TECHO 15 | U2: ARTESANAL | W2: SUPER KK | X2: TIPO 4 | Y2: TECHO 08
B3: FECHA | C3: CLIENTE | D3: SIPAN | E3: CHALPON | F3: CERAM | G3: FORTALEZA | H3: CERAM | I3: TORRE FUERTE | J3: LARK | K3: FORTALEZA | L3: CRUZ CHALPON | M3: TAISON | N3: SIPAN | O3: LARK | P3: ITAL | Q3: FORTALEZA | R3: ITAL | S3: LARK | T3: FORTALEZA | U3: BODOQUE | V3: PEQUEÑO | W3: CERAMICOS | X3: FORTALEZA | Y3: CERAM
A4: INGRESO | D4: ='STOCK 25 a 02'!D24 -> 15211 | E4: ='STOCK 25 a 02'!E24 -> 1670 | F4: ='STOCK 25 a 02'!F24 -> 506 | G4: ='STOCK 25 a 02'!G24 -> 4060 | H4: ='STOCK 25 a 02'!H24 -> 766 | I4: ='STOCK 25 a 02'!I24 -> 103 | J4: ='STOCK 25 a 02'!J24 -> 725 | K4: ='STOCK 25 a 02'!K24 -> 4922 | ... Y4: ='STOCK 25 a 02'!Y24 -> 43
B5: 45355 | C5: M8B-893 | U5: 2200 | V5: 1000
B6: 45356 | C6: M8B-893 | R6: 200
B7: 45357 | C7: M8B-893 | G7: 2000 | K7: 2000
B8: 45357 | C8: M6I-897 | H8: 2000
B9: 45358 | C9: M8B-893 | D9: 3000
B10: 45358 | C10: M6I-897 | U10: 500
A13: SALIDADA | B13: 45355 | C13: VENTAS H&C | G13: 1000 | P13: 150 | U13: 110 | V13: 250 | W13: 800
B14: 403 | C14: VENTA JORDY | G14: 2000
B15: 45356 | C15: VENTAS H&C | D15: 470 | H15: 200
B16: 45356 | C16: VENTA JORDY | K16: 2000 | P16: 500
B17: 45357 | C17: VENTAS H&C | R17: 200
B18: 45359 | C18: VENTAS H&C | H18: 600
A23: SALDO | D23: =SUM(D4:D12)-SUM(D13:D22) -> 17741 | E23: =SUM(E4:E12)-SUM(E13:E22) -> 1670 | F23: =SUM(F4:F12)-SUM(F13:F22) -> 506 | G23: =SUM(G4:G12)-SUM(G13:G22) -> 3060 | H23: =SUM(H4:H12)-SUM(H13:H22) -> 1966 | I23: =SUM(I4:I12)-SUM(I13:I22) -> 103 | J23: =SUM(J4:J12)-SUM(J13:J22) -> 725 | K23: =SUM(K4:K12)-SUM(K13:K22) -> 4922 | ... Y23: =SUM(Y4:Y12)-SUM(Y13:Y22) -> 43
D25: =D23*0.34+(14741*0.01) -> 6179.35 | E25: =+E23*0.4 -> 668 | F25: =+F23*0.38 -> 192.28 | G25: =+G23*0.45 -> 1377 | H25: =+H23*0.59 -> 1159.94 | I25: =+I23*0.6 -> 61.8 | J25: =+J23*0.87 -> 630.75 | K25: =+K23*0.7 -> 3445.4 | L25: =+L23*0.66 -> 0 | M25: =+M23*0.64 -> 640 | N25: =+N23*0.55 -> 495 | O25: =+O23*2.22 -> 266.4 | P25: =+P23*1.75+(286*0.05) -> 2614.8 | Q25: =+Q23*2.26 -> 162.72 | R25: =+R23*1.85 -> 2273.65 | S25: =+S23*2.47 -> 1235 | T25: =+T23*2.36 -> 2055.56 | U25: =+U23*0.42 -> 1134 | V25: =+V23*0.32 -> 1380.8 | W25: =+W23*2+(400*0.3) -> 1320 | X25: =+X23*0.8 -> 224 | Y25: =+Y23*2 -> 86
Y27: =SUM(D25:Y25) -> 27602.45
V28: 24832.45
V29: 6324
D30: 231

Sheet STOCK 10 a 016
D2: PANDERETA | H2: 18 HUECOS | O2: TECHO 12 | R2: TECHO 15 | U2: ARTESANAL | W2: SUPER KK | X2: TIPO 4 | Y2: TECHO 08
B3: FECHA | C3: CLIENTE | D3: SIPAN | E3: CHALPON | F3: CERAM | G3: FORTALEZA | H3: CERAM | I3: TORRE FUERTE | J3: LARK | K3: FORTALEZA | L3: CRUZ CHALPON | M3: TAISON | N3: SIPAN | O3: LARK | P3: ITAL | Q3: FORTALEZA | R3: ITAL | S3: LARK | T3: FORTALEZA | U3: BODOQUE | V3: PEQUEÑO | W3: CERAMICOS | X3: FORTALEZA | Y3: CERAM
A4: INGRESO | D4: ='STOCK 03 a 009'!D23 -> 17741 | E4: ='STOCK 03 a 009'!E23 -> 1670 | F4: ='STOCK 03 a 009'!F23 -> 506 | G4: ='STOCK 03 a 009'!G23 -> 3060 | H4: ='STOCK 03 a 009'!H23 -> 1966 | I4: ='STOCK 03 a 009'!I23 -> 103 | J4: ='STOCK 03 a 009'!J23 -> 725 | K4: ='STOCK 03 a 009'!K23 -> 4922 | ... Y4: ='STOCK 03 a 009'!Y23 -> 43
B5: 45364 | C5: JH FERROC | H5: 2500
B6: 45364 | C6: M8B-893 | D6: 2500
B7: 45365 | C7: M8B-893 | W7: 1200
B8: 45365 | C8: M6I-897 | U8: 2500
B9: 45366 | C9: M6I-897 | P9: 1200
B10: 45366 | C10: M8B-893 | E10: 1000
A14: SALIDADA | B14: 44996 | C14: VENTAS H&C | D14: 200 | G14: 1000 | U14: =2000 -> 2000
B15: 44997 | C15: VENTAS H&C | U15: =490+110 -> 600 | V15: 10
B16: 44998 | C16: VENTAS H&C | D16: 200 | G16: 1000 | M16: =100+250 -> 350 | N16: 900 | R16: =130+160 -> 290
B17: 44999 | C17: VENTA JORDY | P17: 1000
B18: 45000 | C18: VENTAS H&C | D18: 2000 | J18: 500
B19: 45001 | C19: VENTAS H&C | H19: 14 | U19: =500+350 -> 850
A24: SALDO | D24: =SUM(D4:D13)-SUM(D14:D23) -> 17841 | E24: =SUM(E4:E13)-SUM(E14:E23) -> 2670 | F24: =SUM(F4:F13)-SUM(F14:F23) -> 506 | G24: =SUM(G4:G13)-SUM(G14:G23) -> 1060 | H24: =SUM(H4:H13)-SUM(H14:H23) -> 4452 | I24: =SUM(I4:I13)-SUM(I14:I23) -> 103 | J24: =SUM(J4:J13)-SUM(J14:J23) -> 225 | K24: =SUM(K4:K13)-SUM(K14:K23) -> 4922 | ... Y24: =SUM(Y4:Y13)-SUM(Y14:Y23) -> 43
D26: =D24*0.34+(12341*0.01) -> 6189.35 | E26: =+E24*0.4 -> 1068 | F26: =+F24*0.38 -> 192.28 | G26: =+G24*0.45 -> 477 | H26: =+H24*0.54+(1952*0.05) -> 2501.68 | I26: =+I24*0.6 -> 61.8 | J26: =+J24*0.87 -> 195.75 | K26: =+K24*0.7 -> 3445.4 | L26: =+L24*0.66 -> 0 | M26: =+M24*0.64 -> 416 | N26: =+N24*0.55 -> 0 | O26: =+O24*2.22 -> 266.4 | P26: =+P24*1.7+(486*0.05) -> 2890.5 | Q26: =+Q24*2.26 -> 162.72 | R26: =+R24*1.85 -> 1737.15 | S26: =+S24*2.47 -> 1235 | T26: =+T24*2.36 -> 2055.56 | U26: =+U24*0.42 -> 735 | V26: =+V24*0.32 -> 1377.6 | W26: =+W24*2+(400*0.3) -> 3720 | X26: =+X24*0.8 -> 224 | Y26: =+Y24*2 -> 86
Y28: =SUM(D26:Y26) -> 29037.19
D30: 16908 | E30: 2667 | F30: 497 | G30: 1046 | H30: 4520 | J30: 265 | K30: 4906 | M30: 636 | O30: 120 | P30: 1675 | Q30: 71 | R30: 800 | S30: 500 | T30: 870 | U30: =1580+155 -> 1735 | V30: 4290 | W30: 1800 | X30: 280 | Y30: 43
C32: STOCK REAL | D32: =D30-D24 -> -933 | E32: =E30-E24 -> -3 | F32: =F30-F24 -> -9 | G32: =G30-G24 -> -14 | H32: =H30-H24 -> 68 | I32: =I30-I24 -> -103 | J32: =J30-J24 -> 40 | K32: =K30-K24 -> -16 | ... Y32: =Y30-Y24 -> 0
C33: COSTO | D33: 0.35 | E33: 0.4 | F33: 0.38 | G33: 0.45 | H33: 0.54 | I33: 0.6 | J33: 0.87 | K33: 0.7 | M33: 0.64 | P33: 1.75 | Q33: 2.26 | R33: 1.85 | T33: 2.36 | U33: 0.42 | V33: 0.32
D35: =D32*D33 -> -326.55 | E35: =E32*E33 -> -1.2 | F35: =F32*F33 -> -3.42 | G35: =G32*G33 -> -6.3 | H35: =H32*H33 -> 36.72 | I35: =I32*I33 -> -61.8 | J35: =J32*J33 -> 34.8 | K35: =K32*K33 -> -11.2 | ... Y35: =Y32*Y33 -> 0
Y36: =SUM(D35:Y35) -> -640.03
Y37: =Y28+Y36 -> 28397.16

Sheet STOCK 17 a 023
D2: PANDERETA | H2: 18 HUECOS | O2: TECHO 12 | R2: TECHO 15 | U2: ARTESANAL | W2: SUPER KK | X2: TIPO 4 | Y2: TECHO 08
B3: FECHA | C3: CLIENTE | D3: SIPAN | E3: CHALPON | F3: CERAM | G3: FORTALEZA | H3: CERAM | I3: TORRE FUERTE | J3: LARK | K3: FORTALEZA | L3: CRUZ CHALPON | M3: TAISON | N3: SIPAN | O3: LARK | P3: ITAL | Q3: FORTALEZA | R3: ITAL | S3: LARK | T3: FORTALEZA | U3: BODOQUE | V3: PEQUEÑO | W3: CERAMICOS | X3: FORTALEZA | Y3: CERAM
A4: INGRESO | D4: 16908 | E4: 2667 | F4: 497 | G4: 1046 | H4: 4520 | I4: 0 | J4: 265 | K4: 4906 | L4: 0 | M4: 636 | N4: 0 | O4: 120 | P4: 1675 | Q4: 71 | R4: 800 | S4: 500 | T4: 870 | U4: 1735 | V4: 4290 | W4: 1800 | X4: 280 | Y4: 43
B5: 45369 | C5: M8B-893 | J5: 3000
B6: 45369 | C6: M6I-897 | R6: 500
B7: 45370 | C7: M8B-893 | U7: 3000
B8: 45372 | C8: M8B-893 | G8: 2000 | U8: 300
B9: 45373 | C9: M8B-893 | N9: 2000
A12: SALIDADA | B12: 45368 | C12: VENTAS H&C | P12: =6+115 -> 121 | V12: 25
B13: 45369 | C13: VENTAS H&C | G13: 1000 | P13: 130 | V13: 240
B14: 45369 | C14: VENTA JORDY | V14: 1000
B15: 45370 | C15: VENTAS H&C | D15: 1000 | U15: 1000
B16: 45371 | C16: VENTA JORDY | W16: 500
B17: 45371 | C17: VENTAS H&C | D17: 500
B18: 45372 | C18: VENTAS H&C | D18: 760 | P18: 96
B19: 45373 | C19: VENTAS H&C | G19: 500 | R19: 750
A22: SALDO | D22: =SUM(D4:D11)-SUM(D12:D21) -> 14648 | E22: =SUM(E4:E11)-SUM(E12:E21) -> 2667 | F22: =SUM(F4:F11)-SUM(F12:F21) -> 497 | G22: =SUM(G4:G11)-SUM(G12:G21) -> 1546 | H22: =SUM(H4:H11)-SUM(H12:H21) -> 4520 | I22: =SUM(I4:I11)-SUM(I12:I21) -> 0 | J22: =SUM(J4:J11)-SUM(J12:J21) -> 3265 | K22: =SUM(K4:K11)-SUM(K12:K21) -> 4906 | ... Y22: =SUM(Y4:Y11)-SUM(Y12:Y21) -> 43
D24: =D22*0.34+(9148*0.01) -> 5071.8 | E24: =+E22*0.4 -> 1066.8 | F24: =+F22*0.38 -> 188.86 | G24: =+G22*0.43 -> 664.78 | H24: =+H22*0.54+(1952*0.05) -> 2538.4 | I24: =+I22*0.6 -> 0 | J24: =+J22*0.85+(265*0.02) -> 2780.55 | K24: =+K22*0.7 -> 3434.2 | L24: =+L22*0.66 -> 0 | M24: =+M22*0.64 -> 407.04 | N24: =+N22*0.53 -> 1060 | O24: =+O22*2.22 -> 266.4 | P24: =+P22*1.7+(128*0.05) -> 2264 | Q24: =+Q22*2.26 -> 160.46 | R24: =+R22*1.8+(50*0.05) -> 992.5 | S24: =+S22*2.47 -> 1235 | T24: =+T22*2.36 -> 2053.2 | U24: =+U22*0.42 -> 1694.7 | V24: =+V22*0.32 -> 968 | W24: =+W22*2 -> 2600 | X24: =+X22*0.8 -> 224 | Y24: =+Y22*2 -> 86
Y26: =SUM(D24:Y24) -> 29756.69
T31: 4 | W31: =75*3 -> 225
