Workbook

Sheet Hoja1
A2: Cod. Articulo | B2: Descripción | C2: Saldo
A3: 209048 | B3: JR. FOUR LOKO GOLD LATA 473ML X24 | C3: 2 | D3: =VLOOKUP(A3,Ranking!A:F,6,0) -> #N/A
A4: 269002 | B4: JR. FOUR LOKO SANDIA LATA 473ML X24 | C4: 0 | D4: =VLOOKUP(A4,Ranking!A:F,6,0) -> 1
A5: 269026 | B5: JR. FOUR LOKO PURPLE LATA 473ML X24 | C5: 0 | D5: =VLOOKUP(A5,Ranking!A:F,6,0) -> #N/A
A6: 269049 | B6: JR. FOUR LOKO BLUE LATA 473ML X24 | C6: 2 | D6: =VLOOKUP(A6,Ranking!A:F,6,0) -> #N/A
A7: 269050 | B7: JR. FOUR LOKO GREEN LATA 473ML X24 | C7: 2 | D7: =VLOOKUP(A7,Ranking!A:F,6,0) -> 1 | E7: =VLOOKUP(A7,[1]Sheet!$C:$G,5,0) -> 7.92 | F7: =+E7*C7 -> 15.84
A8: 269051 | B8: JR. FOUR LOKO PONCHE DE FRUTAS LATA 473ML X24 | C8: 3 | D8: =VLOOKUP(A8,Ranking!A:F,6,0) -> #N/A
A9: 4980600 | B9: JR. FOUR LOKO MARACUYA LATA 473ML X24 | C9: 0 | D9: =VLOOKUP(A9,Ranking!A:F,6,0) -> #N/A
A10: 4981612 | B10: JR. FOUR LOKO WHITE 473ML X24 | C10: 0 | D10: =VLOOKUP(A10,Ranking!A:F,6,0) -> #N/A
A11: ACO1 | B11: ACT.OLIVA VIDRIO 1LT X24 | C11: 4 | D11: =VLOOKUP(A11,Ranking!A:F,6,0) -> 1 | E11: =VLOOKUP(A11,[1]Sheet!$C:$G,5,0) -> 44 | F11: =+E11*C11 -> 176
A12: ACO14 | B12: ACT.OLIVA VIDRIO 200ML X36 | C12: 6 | D12: =VLOOKUP(A12,Ranking!A:F,6,0) -> 2 | E12: =VLOOKUP(A12,[1]Sheet!$C:$G,5,0) -> 9.5 | F12: =+E12*C12 -> 57
A13: ACO2 | B13: ACT.OLIVA VIDRIO 500ML X36 | C13: 4 | D13: =VLOOKUP(A13,Ranking!A:F,6,0) -> 2 | E13: =VLOOKUP(A13,[1]Sheet!$C:$G,5,0) -> 22 | F13: =+E13*C13 -> 88
A14: ACO3 | B14: ACT.OLIVA VIDRIO 250ML X36 | C14: 0 | D14: =VLOOKUP(A14,Ranking!A:F,6,0) -> #N/A
A15: ACO7 | B15: PACK ACT.OLIVA 4 PRE.VIDRI (1LT+500ML+250ML+JAR.260ML) | C15: 1 | D15: =VLOOKUP(A15,Ranking!A:F,6,0) -> #N/A
A16: ACOJ | B16: ACT.OLIVA VIDRIO JARRITA 260ML X36 | C16: 2 | D16: =VLOOKUP(A16,Ranking!A:F,6,0) -> 2 | E16: =VLOOKUP(A16,[1]Sheet!$C:$G,5,0) -> 13 | F16: =+E16*C16 -> 26
A17: 216001 | B17: ESPUMANTE V.VIEJA NAPOLEON MOSCATO BLANCO 750ML | C17: 0 | D17: =VLOOKUP(A17,Ranking!A:F,6,0) -> #N/A
A18: 700001 | B18: PACK PISCO VARGAS QEBRT 750ML+JAR DE GOMA | C18: 0 | D18: =VLOOKUP(A18,Ranking!A:F,6,0) -> #N/A
A19: 701347 | B19: PACK PISCO VARGAS 750ML+ PISCO VARGAS 125ML | C19: 2 | D19: =VLOOKUP(A19,Ranking!A:F,6,0) -> #N/A
A20: 703444 | B20: PACK VIÑA VIEJA ROSE 750ML+ PISCO VARGAS 125ML | C20: 1 | D20: =VLOOKUP(A20,Ranking!A:F,6,0) -> #N/A
A21: 704236 | B21: VINO VIÑA VIEJA BORGOÑA LATA 473ML X24 | C21: 3 | D21: =VLOOKUP(A21,Ranking!A:F,6,0) -> #N/A
A22: 704237 | B22: VINO VIÑA VIEJA ROSE LATA 473ML | C22: 2 | D22: =VLOOKUP(A22,Ranking!A:F,6,0) -> #N/A
A23: 704422 | B23: VINO VIÑA VIEJA MALBEC LATA 473ML | C23: 14 | D23: =VLOOKUP(A23,Ranking!A:F,6,0) -> #N/A
A24: 704656 | B24: ESPUMANTE V.VIEJA NAPOLEON MOSCATO ROSE X 750ML | C24: 2 | D24: =VLOOKUP(A24,Ranking!A:F,6,0) -> #N/A
A25: 705605 | B25: RON BAHIA BLACK STAR 750ML X12 | C25: 2 | D25: =VLOOKUP(A25,Ranking!A:F,6,0) -> #N/A
A26: 705606 | B26: RON BAHIA GOLD 750ML X12 | C26: 2 | D26: =VLOOKUP(A26,Ranking!A:F,6,0) -> #N/A
A27: 128973 | B27: TAKIS ORIGINAL 56G FLOW BAR EXP X42 | C27: 3 | D27: =VLOOKUP(A27,Ranking!A:F,6,0) -> 1 | E27: =VLOOKUP(A27,[1]Sheet!$C:$G,5,0) -> 1.7 | F27: =+E27*C27 -> 5.1
A28: 128975 | B28: TAKIS XPLOSION 56G FLOW BAR EXP X42 | C28: 4 | D28: =VLOOKUP(A28,Ranking!A:F,6,0) -> #N/A
A29: 128976 | B29: TAKIS FUEGO 56G FLOW BAR EXP X42 | C29: 2 | D29: =VLOOKUP(A29,Ranking!A:F,6,0) -> #N/A
A30: 673 | B30: C&C FRUIT PUNCH 355ML X 24 | C30: 4 | D30: =VLOOKUP(A30,Ranking!A:F,6,0) -> 1 | E30: =VLOOKUP(A30,[1]Sheet!$C:$G,5,0) -> 2.5 | F30: =+E30*C30 -> 10
A31: 675 | B31: C&C GRAPE LATA 355ML X 24 | C31: 1 | D31: =VLOOKUP(A31,Ranking!A:F,6,0) -> 1 | E31: =VLOOKUP(A31,[1]Sheet!$C:$G,5,0) -> 2.5 | F31: =+E31*C31 -> 2.5
A32: 1003001 | B32: TEQUILA JOSE CUER RUB (ESP) 750ML X12 | C32: 1 | D32: =VLOOKUP(A32,Ranking!A:F,6,0) -> #N/A
A33: 1003002 | B33: TEQUILA JOSE C BLANCO(ESP) 750ML X12 | C33: 2 | D33: =VLOOKUP(A33,Ranking!A:F,6,0) -> #N/A
A34: 40000041 | B34: R.CARTAVIO SUPERIOR 750ML X12 | C34: 0 | D34: =VLOOKUP(A34,Ranking!A:F,6,0) -> #N/A
A35: 40000042 | B35: R.CARTAVIO BLACK 750ML X12 | C35: 0 | D35: =VLOOKUP(A35,Ranking!A:F,6,0) -> #N/A
A36: 40000055 | B36: R.CARTAVIO XO 50ML X120 | C36: 0 | D36: =VLOOKUP(A36,Ranking!A:F,6,0) -> 1
A37: 40000106 | B37: WHIS.OLD TIMES BLACK 750ML X12 | C37: 0 | D37: =VLOOKUP(A37,Ranking!A:F,6,0) -> #N/A
A38: 40000107 | B38: WHIS.OLD TIMES RED 750ML X12 | C38: 0 | D38: =VLOOKUP(A38,Ranking!A:F,6,0) -> #N/A
A39: 40000108 | B39: VODKA RUSSKAYA 750ML X12 | C39: 0 | D39: =VLOOKUP(A39,Ranking!A:F,6,0) -> #N/A
A40: 40000157 | B40: R.CARTAVIO XO 750ML X6 | C40: 2 | D40: =VLOOKUP(A40,Ranking!A:F,6,0) -> #N/A
A41: 40000785 | B41: R.CARTAVIO RESERVA 750ML X12 | C41: 1 | D41: =VLOOKUP(A41,Ranking!A:F,6,0) -> #N/A
...

Sheet tienda
A1: Cod. Articulo | B1: Descripción | C1: Precio | D1: Costo | E1: Proveedor | F1: Saldo | G1: RETORNAR | H1: FACTURAR | I1: queda stock en Tienda | J1: saldo | K1: Soles | L1: EMPRESA
A2: 209048 | B2: JR. FOUR LOKO GOLD LATA 473ML X24 | C2: =VLOOKUP(A2,[2]Hoja2!$A:$F,6,0) -> 9.1 | D2: 7.92 | E2: 4LO | F2: 2 | H2: 2 | I2: =+F2-G2-H2 -> 0 | J2: =+F2-G2-H2-I2 -> 0 | K2: =+H2*D2 -> 15.84 | L2: CL1 | M2: f112-531
A3: 269002 | B3: JR. FOUR LOKO SANDIA LATA 473ML X24 | D3: 7.92 | E3: 4LO | F3: 0 | J3: =+F3-G3-H3-I3 -> 0 | O3: Etiquetas de fila | P3: Suma de Soles
A4: 269026 | B4: JR. FOUR LOKO PURPLE LATA 473ML X24 | D4: 7.92 | E4: 4LO | F4: 0 | J4: =+F4-G4-H4-I4 -> 0 | O4: 4LO | P4: 63.36
A5: 269049 | B5: JR. FOUR LOKO BLUE LATA 473ML X24 | C5: =VLOOKUP(A5,[2]Hoja2!$A:$F,6,0) -> 9.1 | D5: 7.92 | E5: 4LO | F5: 2 | H5: 2 | I5: =+F5-G5-H5 -> 0 | J5: =+F5-G5-H5-I5 -> 0 | K5: =+H5*D5 -> 15.84 | L5: CL1 | M5: f112-507 | O5: AGC | P5: 160.95
A6: 269050 | B6: JR. FOUR LOKO GREEN LATA 473ML X24 | C6: =VLOOKUP(A6,[2]Hoja2!$A:$F,6,0) -> 9.1 | D6: 7.92 | E6: 4LO | F6: 1 | H6: 1 | I6: =+F6-G6-H6 -> 0 | J6: =+F6-G6-H6-I6 -> 0 | K6: =+H6*D6 -> 7.92 | L6: CL1 | M6: F112-507 | O6: AVV | P6: 47.8
A7: 269051 | B7: JR. FOUR LOKO PONCHE DE FRUTAS LATA 473ML X24 | C7: =VLOOKUP(A7,[2]Hoja2!$A:$F,6,0) -> 9.1 | D7: 7.92 | E7: 4LO | F7: 3 | H7: 3 | I7: =+F7-G7-H7 -> 0 | J7: =+F7-G7-H7-I7 -> 0 | K7: =+H7*D7 -> 23.76 | L7: CL1 | O7: BIM | P7: 15.3
A8: 4980600 | B8: JR. FOUR LOKO MARACUYA LATA 473ML X24 | D8: 7.92 | E8: 4LO | F8: 0 | J8: =+F8-G8-H8-I8 -> 0 | O8: C&C | P8: 10
A9: 4981612 | B9: JR. FOUR LOKO WHITE 473ML X24 | D9: 7.92 | E9: 4LO | F9: 0 | J9: =+F9-G9-H9-I9 -> 0 | O9: CAR | P9: 268.15
A10: ACO1 | B10: ACT.OLIVA VIDRIO 1LT X24 | C10: =VLOOKUP(A10,[2]Hoja3!$D:$P,13,0) -> 55.1 | D10: 44 | E10: AGC | F10: 4 | H10: 1 | I10: =+F10-G10-H10 -> 3 | J10: =+F10-G10-H10-I10 -> 0 | K10: =+H10*D10 -> 44 | L10: CL1 | M10: F111-159746 | O10: COP | P10: 151.25
A11: ACO14 | B11: ACT.OLIVA VIDRIO 200ML X36 | C11: =VLOOKUP(A11,[2]Hoja3!$D:$P,13,0) -> 12.3 | D11: 9.5 | E11: AGC | F11: 6 | H11: 1 | I11: =+F11-G11-H11 -> 5 | J11: =+F11-G11-H11-I11 -> 0 | K11: =+H11*D11 -> 9.5 | L11: CL1 | M11: F111-159746 | O11: ESM | P11: 26
A12: ACO2 | B12: ACT.OLIVA VIDRIO 500ML X36 | C12: =VLOOKUP(A12,[2]Hoja3!$D:$P,13,0) -> 28.15 | D12: 22 | E12: AGC | F12: 4 | H12: 1 | I12: =+F12-G12-H12 -> 3 | J12: =+F12-G12-H12-I12 -> 0 | K12: =+H12*D12 -> 22 | L12: CL1 | M12: F111-159746 | O12: EXC | P12: 0
A13: ACO3 | B13: ACT.OLIVA VIDRIO 250ML X36 | D13: 13.5 | E13: AGC | F13: 0 | G13: 0 | J13: =+F13-G13-H13-I13 -> 0 | O13: FDL | P13: 0
A14: ACO7 | B14: PACK ACT.OLIVA 4 PRE.VIDRI (1LT+500ML+250ML+JAR.260ML) | C14: =VLOOKUP(A14,[2]Hoja3!$D:$P,13,0) -> 82.8 | D14: 72.45 | E14: AGC | F14: 1 | H14: 1 | I14: =+F14-G14-H14 -> 0 | J14: =+F14-G14-H14-I14 -> 0 | K14: =+H14*D14 -> 72.45 | L14: CL1 | O14: GCC | P14: 4.8
A15: ACOJ | B15: ACT.OLIVA VIDRIO JARRITA 260ML X36 | C15: =VLOOKUP(A15,[2]Hoja3!$D:$P,13,0) -> 17 | D15: 13 | E15: AGC | F15: 2 | H15: 1 | I15: =+F15-G15-H15 -> 1 | J15: =+F15-G15-H15-I15 -> 0 | K15: =+H15*D15 -> 13 | L15: CL1 | M15: F111-137631 | O15: GCP | P15: 11.65
A16: 216001 | B16: ESPUMANTE V.VIEJA NAPOLEON MOSCATO BLANCO 750ML | D16: 8.73 | E16: AVV | F16: 0 | G16: 0 | J16: =+F16-G16-H16-I16 -> 0 | O16: GKP | P16: 52
A17: 700001 | B17: PACK PISCO VARGAS QEBRT 750ML+JAR DE GOMA | D17: 27.3 | E17: AVV | F17: 0 | G17: 0 | J17: =+F17-G17-H17-I17 -> 0 | O17: ISM
A18: 701347 | B18: PACK PISCO VARGAS 750ML+ PISCO VARGAS 125ML | C18: =VLOOKUP(A18,[2]Hoja2!$A:$F,6,0) -> 23.55 | D18: 19.3 | E18: AVV | F18: 2 | H18: 1 | I18: =+F18-G18-H18 -> 1 | J18: =+F18-G18-H18-I18 -> 0 | K18: =+H18*D18 -> 19.3 | L18: CL1 | O18: IWA | P18: 406.97
A19: 703444 | B19: PACK VIÑA VIEJA ROSE 750ML+ PISCO VARGAS 125ML | C19: =VLOOKUP(A19,[2]Hoja2!$A:$F,6,0) -> 12.86 | D19: 11.09 | E19: AVV | F19: 1 | G19: 1 | J19: =+F19-G19-H19-I19 -> 0 | K19: =+H19*D19 -> 0 | O19: JEI | P19: 0
A20: 704236 | B20: VINO VIÑA VIEJA BORGOÑA LATA 473ML X24 | C20: =VLOOKUP(A20,[2]Hoja2!$A:$F,6,0) -> 5.88 | D20: 4.75 | E20: AVV | F20: 3 | H20: 2 | I20: =+F20-G20-H20 -> 1 | J20: =+F20-G20-H20-I20 -> 0 | K20: =+H20*D20 -> 9.5 | L20: CL1 | O20: JYA | P20: 314
A21: 704237 | B21: VINO VIÑA VIEJA ROSE LATA 473ML | C21: =VLOOKUP(A21,[2]Hoja2!$A:$F,6,0) -> 5.88 | D21: 4.75 | E21: AVV | F21: 2 | H21: 2 | I21: =+F21-G21-H21 -> 0 | J21: =+F21-G21-H21-I21 -> 0 | K21: =+H21*D21 -> 9.5 | L21: CL1 | O21: K&M | P21: 10.5
A22: 704422 | B22: VINO VIÑA VIEJA MALBEC LATA 473ML | C22: =VLOOKUP(A22,[2]Hoja2!$A:$F,6,0) -> 5.88 | D22: 4.75 | E22: AVV | F22: 14 | H22: 2 | I22: =+F22-G22-H22 -> 12 | J22: =+F22-G22-H22-I22 -> 0 | K22: =+H22*D22 -> 9.5 | L22: CL1 | O22: KLS | P22: 133.93
A23: 704656 | B23: ESPUMANTE V.VIEJA NAPOLEON MOSCATO ROSE X 750ML | C23: =VLOOKUP(A23,[2]Hoja2!$A:$F,6,0) -> 10.33 | D23: 8.73 | E23: AVV | F23: 2 | G23: 2 | J23: =+F23-G23-H23-I23 -> 0 | K23: =+H23*D23 -> 0 | O23: OCU | P23: 0
A24: 705605 | B24: RON BAHIA BLACK STAR 750ML X12 | C24: =VLOOKUP(A24,[2]Hoja2!$A:$F,6,0) -> 16.51 | D24: 14.11 | E24: AVV | F24: 2 | G24: 2 | J24: =+F24-G24-H24-I24 -> 0 | K24: =+H24*D24 -> 0 | O24: OTR | P24: 152.98
A25: 705606 | B25: RON BAHIA GOLD 750ML X12 | C25: =VLOOKUP(A25,[2]Hoja2!$A:$F,6,0) -> 16.51 | D25: 14.11 | E25: AVV | F25: 2 | G25: 2 | J25: =+F25-G25-H25-I25 -> 0 | K25: =+H25*D25 -> 0 | O25: PAN | P25: 26.9
A26: 128973 | B26: TAKIS ORIGINAL 56G FLOW BAR EXP X42 | C26: =VLOOKUP(A26,[2]Hoja3!$D:$P,13,0) -> 2.5 | D26: 1.7 | E26: BIM | F26: 3 | H26: 3 | I26: =+F26-G26-H26 -> 0 | J26: =+F26-G26-H26-I26 -> 0 | K26: =+H26*D26 -> 5.1 | L26: CL1 | O26: PBA | P26: 334.9
A27: 128975 | B27: TAKIS XPLOSION 56G FLOW BAR EXP X42 | C27: =VLOOKUP(A27,[2]Hoja3!$D:$P,13,0) -> 2.5 | D27: 1.7 | E27: BIM | F27: 4 | H27: 4 | I27: =+F27-G27-H27 -> 0 | J27: =+F27-G27-H27-I27 -> 0 | K27: =+H27*D27 -> 6.8 | L27: CL1 | O27: PFA | P27: 611.05
A28: 128976 | B28: TAKIS FUEGO 56G FLOW BAR EXP X42 | C28: =VLOOKUP(A28,[2]Hoja3!$D:$P,13,0) -> 2.5 | D28: 1.7 | E28: BIM | F28: 2 | H28: 2 | I28: =+F28-G28-H28 -> 0 | J28: =+F28-G28-H28-I28 -> 0 | K28: =+H28*D28 -> 3.4 | L28: CL1 | O28: PIC
A29: 673 | B29: C&C FRUIT PUNCH 355ML X 24 | C29: =VLOOKUP(A29,[2]Hoja2!$A:$F,6,0) -> 2.99 | D29: 2.5 | E29: C&C | F29: 4 | H29: 3 | I29: =+F29-G29-H29 -> 1 | J29: =+F29-G29-H29-I29 -> 0 | K29: =+H29*D29 -> 7.5 | L29: CL2 | O29: PRE | P29: 82.88
A30: 675 | B30: C&C GRAPE LATA 355ML X 24 | C30: =VLOOKUP(A30,[2]Hoja2!$A:$F,6,0) -> 2.99 | D30: 2.5 | E30: C&C | F30: 1 | H30: 1 | I30: =+F30-G30-H30 -> 0 | J30: =+F30-G30-H30-I30 -> 0 | K30: =+H30*D30 -> 2.5 | L30: CL2 | O30: PRR | P30: 2542.93
A31: 1003001 | B31: TEQUILA JOSE CUER RUB (ESP) 750ML X12 | C31: 49.98 | D31: 48.42 | E31: CAR | F31: 1 | G31: 1 | J31: =+F31-G31-H31-I31 -> 0 | K31: =+H31*D31 -> 0 | O31: RPD | P31: 254.46
A32: 1003002 | B32: TEQUILA JOSE C BLANCO(ESP) 750ML X12 | C32: =VLOOKUP(A32,[2]Hoja2!$A:$F,6,0) -> 59.76 | D32: 52 | E32: CAR | F32: 2 | G32: 2 | J32: =+F32-G32-H32-I32 -> 0 | K32: =+H32*D32 -> 0 | O32: RTD
A33: 40000041 | B33: R.CARTAVIO SUPERIOR 750ML X12 | D33: 20.62 | E33: CAR | F33: 0 | G33: 0 | J33: =+F33-G33-H33-I33 -> 0 | O33: SAL | P33: 0
A34: 40000042 | B34: R.CARTAVIO BLACK 750ML X12 | D34: 20.61 | E34: CAR | F34: 0 | G34: 0 | J34: =+F34-G34-H34-I34 -> 0 | O34: SIG
A35: 40000055 | B35: R.CARTAVIO XO 50ML X120 | D35: 13.78 | E35: CAR | F35: 0 | J35: =+F35-G35-H35-I35 -> 0 | O35: SQL | P35: 153.08
A36: 40000106 | B36: WHIS.OLD TIMES BLACK 750ML X12 | D36: 20.86 | E36: CAR | F36: 0 | G36: 0 | J36: =+F36-G36-H36-I36 -> 0 | O36: TCM | P36: 66.17
A37: 40000107 | B37: WHIS.OLD TIMES RED 750ML X12 | D37: 19.36 | E37: CAR | F37: 0 | G37: 0 | J37: =+F37-G37-H37-I37 -> 0 | O37: VDO | P37: 0
A38: 40000108 | B38: VODKA RUSSKAYA 750ML X12 | D38: 18.62 | E38: CAR | F38: 0 | G38: 0 | J38: =+F38-G38-H38-I38 -> 0 | O38: YIC | P38: 175.41
A39: 40000157 | B39: R.CARTAVIO XO 750ML X6 | C39: =VLOOKUP(A39,[2]Hoja2!$A:$F,6,0) -> 196.71 | D39: 163.86 | E39: CAR | F39: 2 | I39: 2 | J39: =+F39-G39-H39-I39 -> 0 | K39: =+H39*D39 -> 0 | O39: (en blanco)
A40: 40000785 | B40: R.CARTAVIO RESERVA 750ML X12 | C40: =VLOOKUP(A40,[2]Hoja2!$A:$F,6,0) -> 45.97 | D40: 37.26 | E40: CAR | F40: 1 | H40: 1 | I40: =+F40-G40-H40 -> 0 | J40: =+F40-G40-H40-I40 -> 0 | K40: =+H40*D40 -> 37.26 | L40: CL2 | O40: Total general | P40: 6077.42 | Q40: =+GETPIVOTDATA("Soles",$O$3)*5% -> 303.871 | R40: =+GETPIVOTDATA("Soles",$O$3)+Q40 -> 6381.291
...

Sheet ABC
A1: CodigoInternoAux | B1: Descripcion | C1: CantidadVendida | D1: ABC
A2: 403859 | B2: BIFE ANGOSTO CHOICE 2U X 300GR | C2: 11 | D2: A
A3: CHAR07 | B3: CH. FINAS HIERBAS | C3: 9 | D3: A
A4: CHAR10 | B4: CH.ARTESANAL PARRILLERO | C4: 7 | D4: A
A5: 102025 | B5: BENEDIKTINER FESTBIER LATA 500 ML | C5: 6 | D5: A
A6: ENT104 | B6: ENTRAÑA FINA ANGUS 0.75KG - 1KG | C6: 6 | D6: A
A7: CHAR04 | B7: CHIMICHURRI CLASICO | C7: 5 | D7: A
A8: EMGR016 | B8: CHORIZO MERME-ROCOTO 140G OSSO | C8: 5 | D8: A
A9: IMP00057 | B9: TOMAHAWH STERLING 1.3 - 1.5 KG | C9: 4 | D9: A
A10: 0504001 | B10: C/T FRONT.CABERNET SAUVIGNON 750ML X12 | C10: 4 | D10: A
A11: DUFF01 | B11: DUFF LATA 330ML X 4 | C11: 4 | D11: A
A12: BFA001 | B12: BIFE ANGOSTO MADURADO GRAIN FED ANGUS 800GR-1.2KG | C12: 3 | D12: A
A13: NMP16 | B13: CERVEZA MODELO ESPECIAL BT 355ML X 12 | C13: 3 | D13: A
... A68: WHI0348 | B68: WHIS.JOHNNIE W.RED LABEL 750ML X12 | C68: 1 | D68: C

Sheet Ranking
A1: CodigoInternoAux | B1: Descripcion | C1: CantidadVendida | D1: Ranking | E1: PromedioDiario | F1: PromedioMensual | G1: %Participacion | H1: %Acum | I1: ABC
A2: 403859 | B2: BIFE ANGOSTO CHOICE 2U X 300GR | C2: 11 | D2: 1 | E2: 0.35483871 | F2: 11 | G2: 0.072847682 | H2: 0.072847682 | I2: A
A3: CHAR07 | B3: CH. FINAS HIERBAS | C3: 9 | D3: 2 | E3: 0.29032258 | F3: 9 | G3: 0.059602649 | H3: 0.13245033 | I3: A
A4: CHAR10 | B4: CH.ARTESANAL PARRILLERO | C4: 7 | D4: 3 | E4: 0.22580645 | F4: 7 | G4: 0.046357616 | H4: 0.17880795 | I4: A
A5: 102025 | B5: BENEDIKTINER FESTBIER LATA 500 ML | C5: 6 | D5: 4 | E5: 0.19354839 | F5: 6 | G5: 0.039735099 | H5: 0.21854305 | I5: A
A6: ENT104 | B6: ENTRAÑA FINA ANGUS 0.75KG - 1KG | C6: 6 | D6: 5 | E6: 0.19354839 | F6: 6 | G6: 0.039735099 | H6: 0.25827815 | I6: A
A7: CHAR04 | B7: CHIMICHURRI CLASICO | C7: 5 | D7: 6 | E7: 0.16129032 | F7: 5 | G7: 0.033112583 | H7: 0.29139073 | I7: A
A8: EMGR016 | B8: CHORIZO MERME-ROCOTO 140G OSSO | C8: 5 | D8: 7 | E8: 0.16129032 | F8: 5 | G8: 0.033112583 | H8: 0.32450331 | I8: A
A9: IMP00057 | B9: TOMAHAWH STERLING 1.3 - 1.5 KG | C9: 4 | D9: 8 | E9: 0.12903226 | F9: 4 | G9: 0.026490066 | H9: 0.35099338 | I9: A
A10: 0504001 | B10: C/T FRONT.CABERNET SAUVIGNON 750ML X12 | C10: 4 | D10: 9 | E10: 0.12903226 | F10: 4 | G10: 0.026490066 | H10: 0.37748344 | I10: A
A11: DUFF01 | B11: DUFF LATA 330ML X 4 | C11: 4 | D11: 10 | E11: 0.12903226 | F11: 4 | G11: 0.026490066 | H11: 0.40397351 | I11: A
A12: BFA001 | B12: BIFE ANGOSTO MADURADO GRAIN FED ANGUS 800GR-1.2KG | C12: 3 | D12: 11 | E12: 0.096774194 | F12: 3 | G12: 0.01986755 | H12: 0.42384106 | I12: A
A13: NMP16 | B13: CERVEZA MODELO ESPECIAL BT 355ML X 12 | C13: 3 | D13: 12 | E13: 0.096774194 | F13: 3 | G13: 0.01986755 | H13: 0.44370861 | I13: A
... A68: WHI0348 | B68: WHIS.JOHNNIE W.RED LABEL 750ML X12 | C68: 1 | D68: 67 | E68: 0.032258065 | F68: 1 | G68: 0.0066225166 | H68: 1 | I68: C
